Workbook

Sheet P&G
A2: =Summary!A2 -> NAFASI WATER - ARNOT WASTE TREATMENT PLANT | G2: =Summary!C2 -> Revision T1
A3: PRELIMINARY AND GENERAL
A4: SECTION 1 - BILL OF QUANTITIES | G4: =+Summary!C4 -> 45183
A6: ITEM NO | B6: PAY REF | C6: DESCRIPTION | D6: UNIT | E6: QTY | F6: RATE | G6: AMOUNT
B8: SANS 1200A | C8: SECTION 1 - PRELIMINARY AND GENERAL
C9: (Applicable to the whole of the Works)
B11: 8.3 | C11: FIXED CHARGE ITEMS
A13: 1 | B13: 8.3.1 | C13: Contractual requirements (excluding insurance and performance bond) | D13: SUM | E13: 1 | G13: =+E13*F13 -> 0
B15: 8.3.2 | C15: Establishment of Facilities on the Site
B17: 8.3.2.1 | C17: Facilities for Engineer
B19: 8.3.2.1a | C19: Furnished Office (1 No) | D19: SUM | E19: 1 | G19: =+E19*F19 -> 0
B21: 8.3.2.1c | C21: Nameboard (1 No). | D21: SUM | E21: 1 | G21: =+E21*F21 -> 0
B23: 8.3.2.2 | C23: Facilities for Contractor
A25: 2 | B25: 8.3.2.2a | C25: Offices and storage sheds. | D25: SUM | E25: 1 | G25: =+E25*F25 -> 0
A27: 3 | B27: 8.3.2.2b | C27: Workshops. | D27: SUM | E27: 1 | G27: =+E27*F27 -> 0
A29: 4 | B29: 8.3.2.2c | C29: Laboratories. | D29: SUM | E29: 1 | G29: =+E29*F29 -> 0
A31: 5 | B31: 8.3.2.2d | C31: Living accommodation. | D31: SUM | E31: 1 | G31: =+E31*F31 -> 0
A33: 6 | B33: 8.3.2.2e | C33: Ablution and latrine facilities. | D33: SUM | E33: 1 | G33: =+E33*F33 -> 0
A35: 7 | B35: 8.3.2.2f | C35: Tools and equipment. | D35: SUM | E35: 1 | G35: =+E35*F35 -> 0
A37: 8 | B37: 8.3.2.2g | C37: Water supplies, electric power and communications | D37: SUM | E37: 1 | G37: =+E37*F37 -> 0
A39: 9 | B39: 8.3.2.2h | C39: Dealing with water | D39: SUM | E39: 1 | G39: =+E39*F39 -> 0
A41: 10 | B41: 8.3.2.2i | C41: Access | D41: SUM | E41: 1 | G41: =+E41*F41 -> 0
A43: 11 | B43: 8.3.2.2j | C43: Plant | D43: SUM | E43: 1 | G43: =+E43*F43 -> 0
A45: 12 | B45: 8.3.3 | C45: Other fixed charge obligations. | D45: SUM | E45: 1 | G45: =+E45*F45 -> 0
A47: 13 | B47: 8.3.4 | C47: Removal of site establishment. | D47: SUM | E47: 1 | G47: =+E47*F47 -> 0
... A51: 15 | B51: PSA 8.3.6 | C51: Performance Bond | D51: SUM | E51: 1 | G51: =+E51*F51 -> 0
B53: 8.3 | C53: VALUE RELATED ITEMS
A55: 16 | B55: 8.3.1 | C55: Contractual requirements (excluding insurance and performance bond) | D55: SUM | E55: 1 | G55: =+E55*F55 -> 0
A60: CARRIED FORWARD | G60: =SUM(G7:G59) -> 0
A63: ITEM NO | B63: PAY REF | C63: DESCRIPTION | D63: UNIT | E63: QTY | F63: RATE | G63: AMOUNT
A64: BROUGHT FORWARD | G64: =+G60 -> 0
B66: 8.3.2 | C66: Establishment of Facilities on the Site
B68: 8.3.2.1 | C68: Facilities for Engineer
A70: 17 | B70: 8.3.2.1a | C70: Furnished Office (1 No) | D70: SUM | E70: 1 | G70: =+E70*F70 -> 0
A72: 18 | B72: 8.3.2.1c | C72: Nameboard (1 No). | D72: SUM | E72: 1 | G72: =+E72*F72 -> 0
B74: 8.3.2.2 | C74: Facilities for Contractor
A76: 19 | B76: 8.3.2.2a | C76: Offices and storage sheds. | D76: SUM | E76: 1 | G76: =+E76*F76 -> 0
A78: 20 | B78: 8.3.2.2b | C78: Workshops. | D78: SUM | E78: 1 | G78: =+E78*F78 -> 0
A80: 21 | B80: 8.3.2.2c | C80: Laboratories. | D80: SUM | E80: 1 | G80: =+E80*F80 -> 0
A82: 22 | B82: 8.3.2.2d | C82: Living accommodation. | D82: SUM | E82: 1 | G82: =+E82*F82 -> 0
...

Sheet RO Building
A1: GEORGE BIOMASS POWER PLANT
A2: =Summary!A2 -> NAFASI WATER - ARNOT WASTE TREATMENT PLANT | G2: =Summary!C2 -> Revision T1
A3: =Summary!A3 -> PILING AND CIVIL WORK
A4: SECTION 2 - BILL OF QUANTITIES | G4: =Summary!C4 -> 45183
A6: ITEM NO | B6: PAY REF | C6: DESCRIPTION | D6: UNIT | E6: QTY | F6: RATE | G6: AMOUNT | I6: Foundations | J6: Surface Bed | K6: Building Works | L6: Pump Plinths
C8: RO BUILDING
B10: SANS 1200F | C10: PILING (BORED PILES) | E10: =IF(SUM(H10:R10)>0,SUM(H10:R10),"")
E11: =IF(SUM(H11:R11)>0,SUM(H11:R11),"")
C12: Move equipment and setup: | E12: =IF(SUM(H12:R12)>0,SUM(H12:R12),"")
E13: =IF(SUM(H13:R13)>0,SUM(H13:R13),"")
A14: 1 | C14: Move equipment to and set up each pile position for heavy bored cast-in-situ piles (610mm Pile diameter) | D14: No | E14: =SUM(I14:S14) -> 0 | F14: 1150 | G14: =+E14*F14 -> 0 | I14: 0 | J14: 0 | K14: 0 | L14: 0
C16: Bore Holes for Piles:
C17: Bored holes for cast-in-situ piles of 610mm diameter (heavy) through material situated in the following successive depth ranges:
A19: 2 | C19: 0m up to 10m | D19: m | E19: =SUM(I19:S19) -> 0 | F19: 1850 | G19: =+E19*F19 -> 0 | I19: =I14*10 -> 0 | J19: =J14*10 -> 0 | K19: =K14*10 -> 0 | L19: =L14*10 -> 0
A21: 3 | C21: 10m up to 20m | D21: m | E21: =SUM(I21:S21) -> 0 | F21: =F19 -> 1850 | G21: =+E21*F21 -> 0 | I21: =I14*5 -> 0 | J21: =J14*5 -> 0 | K21: =K14*5 -> 0 | L21: =L14*5 -> 0
C23: Forming of Bulbous bases:
A25: 4 | C25: For DCS piles of 610mm diameter | D25: No | E25: =SUM(I25:S25) -> 0 | F25: 1250 | G25: =+E25*F25 -> 0 | I25: =I14 -> 0 | J25: =J14 -> 0 | K25: =K14 -> 0 | L25: =L14 -> 0
C27: Steel reinforcement in cast-in-situ piles:
A29: 5 | C29: Mild steel, Plain | D29: t | E29: =SUM(I29:S29) -> 0 | F29: 29500 | G29: =+E29*F29 -> 0 | I29: =(I19+I21)*0.00325 -> 0 | J29: =(J19+J21)*0.00325 -> 0 | K29: =(K19+K21)*0.00325 -> 0 | L29: =(L19+L21)*0.00325 -> 0
A31: 6 | C31: High yield stress steel | D31: t | E31: =SUM(I31:S31) -> 0 | F31: 28000 | G31: =+E31*F31 -> 0 | I31: =(I19+I21)*0.0215 -> 0 | J31: =(J19+J21)*0.0215 -> 0 | K31: =(K19+K21)*0.0215 -> 0 | L31: =(L19+L21)*0.0215 -> 0
C33: Concrete for cast-in-situ piles, under reams and sockets:
A35: 7 | C35: Compressive Strength 30Mpa/19mm
C37: Piles | D37: m3 | E37: =SUM(I37:S37) -> 0 | F37: 3500 | G37: =+E37*F37 -> 0 | I37: =((I19+I21)*0.292)+(I14*0.75) -> 0 | J37: =((J19+J21)*0.292)+(J14*0.75) -> 0 | K37: =((K19+K21)*0.292)+(K14*0.75) -> 0 | L37: =((L19+L21)*0.292)+(L14*0.75) -> 0
B39: PSF 8.2.20 | C39: Strip / cut heads off:
A41: 8 | C41: 610mm diameter bored pile | D41: No | E41: =SUM(I41:S41) -> 0 | F41: 875 | G41: =+E41*F41 -> 0 | I41: =I14 -> 0 | J41: =J14 -> 0 | K41: =K14 -> 0 | L41: =L14 -> 0
B43: SANS 1200D | C43: EARTHWORKS
A45: 9 | B45: 8.3.3 | C45: Rip and scarify in-situ material for a depth of 150mm, breaking down oversize material, adding suitable material where necessary and compact to 93% Mod AASHTO density | D45: m2 | E45: =SUM(I45:S45) -> 1485 | F45: 225 | G45: =+E45*F45 -> 334125 | J45: 1485
A50: CARRIED FORWARD | G50: =SUM(G7:G49) -> 334125
A53: ITEM NO | B53: PAY REF | C53: DESCRIPTION | D53: UNIT | E53: QTY | F53: RATE | G53: AMOUNT
A54: BROUGHT FORWARD | G54: =+G50 -> 334125
B56: 1200D | C56: EARTHWORKS
B58: 8.3.3 | C58: Restricted excavation
C60: Excavation for restricted foundations in all materials and dispose spoil material at a site provided by the Contractor
A62: 10 | C62: Depth up to 2m | D62: m3 | E62: =SUM(I62:S62) -> 106 | F62: 175 | G62: =+E62*F62 -> 18550 | I62: 106 | J62: 0
C64: Extra overs on Item above for:
A66: 11 | C66: Soilcrete backfill under structures as indicated on the drawings or directed by the Engineer | D66: m3 | E66: =SUM(I66:S66) -> 0 | F66: 950 | G66: =+E66*F66 -> 0 | I66: 0 | J66: 0
C68: (The aggregate of soilcrete shall be mixed with 5% cement of volume and shall consist of approved soil or gravel containing stones, obtained from commercial sources, not bigger than 38mm and with a plasticity index not exceeding 10)
B70: 8.3.4 | C70: Importing of materials
C72: Extra over item for importation of materials from commercial sources:
A74: 12 | C74: Backfill with G5 material compacted to 93% MOD AASHTO from commercial sources selected by the Contractor | D74: m3 | E74: =SUM(I74:S74) -> 55 | F74: 725 | G74: =+E74*F74 -> 39875 | I74: 55
...

Sheet Chemical Store
A1: GEORGE BIOMASS POWER PLANT
A2: =Summary!A2 -> NAFASI WATER - ARNOT WASTE TREATMENT PLANT | G2: =Summary!C2 -> Revision T1
A3: =Summary!A3 -> PILING AND CIVIL WORK
A4: SECTION 3 - BILL OF QUANTITIES | G4: =Summary!C4 -> 45183
A6: ITEM NO | B6: PAY REF | C6: DESCRIPTION | D6: UNIT | E6: QTY | F6: RATE | G6: AMOUNT | I6: Foundations | J6: Surface Beds | K6: Building Works
C8: CHEMICAL STORE
B10: SANS 1200F | C10: PILING (BORED PILES) | E10: =IF(SUM(H10:M10)>0,SUM(H10:M10),"")
E11: =IF(SUM(H11:M11)>0,SUM(H11:M11),"")
C12: Move equipment and setup: | E12: =IF(SUM(H12:M12)>0,SUM(H12:M12),"")
E13: =IF(SUM(H13:M13)>0,SUM(H13:M13),"")
A14: 1 | C14: Move equipment to and set up each pile position for heavy bored cast-in-situ piles (610mm diameter) | D14: No | E14: =SUM(I14:N14) -> 0 | F14: 1150 | G14: =+E14*F14 -> 0 | I14: 0 | J14: 0 | K14: 0 | L14: 0 | M14: 0 | N14: 0
C16: Bore Holes for Piles:
C17: Bored holes for cast-in-situ piles of 610mm diameter (heavy) through material situated in the following successive depth ranges:
A19: 2 | C19: 0m up to 10m | D19: m | E19: =SUM(I19:N19) -> 0 | F19: 1850 | G19: =+E19*F19 -> 0 | I19: =I14*10 -> 0 | J19: =J14*10 -> 0 | K19: =K14*10 -> 0 | L19: =L14*10 -> 0 | M19: =M14*10 -> 0 | N19: =N14*10 -> 0
A21: 3 | C21: 10m up to 20m | D21: m | E21: =SUM(I21:N21) -> 0 | F21: =F19 -> 1850 | G21: =+E21*F21 -> 0 | I21: =I14*5 -> 0 | J21: =J14*5 -> 0 | K21: =K14*5 -> 0 | L21: =L14*5 -> 0 | M21: =M14*5 -> 0 | N21: =N14*5 -> 0
C23: Forming of Bulbous bases:
A25: 4 | C25: For DCS piles of 610mm diameter | D25: No | E25: =SUM(I25:N25) -> 0 | F25: 1250 | G25: =+E25*F25 -> 0 | I25: =I14 -> 0 | J25: =J14 -> 0 | K25: =K14 -> 0 | L25: =L14 -> 0 | M25: =M14 -> 0 | N25: =N14 -> 0
C27: Steel reinforcement in cast-in-situ piles:
A29: 5 | C29: Mild steel, Plain | D29: t | E29: =SUM(I29:N29) -> 0 | F29: 29500 | G29: =+E29*F29 -> 0 | I29: =(I19+I21)*0.00325 -> 0 | J29: =(J19+J21)*0.00325 -> 0 | K29: =(K19+K21)*0.00325 -> 0 | L29: =(L19+L21)*0.00325 -> 0 | M29: =(M19+M21)*0.00325 -> 0 | N29: =(N19+N21)*0.00325 -> 0
A31: 6 | C31: High yield stress steel | D31: t | E31: =SUM(I31:AG31) -> 0 | F31: 28000 | G31: =+E31*F31 -> 0 | I31: =(I19+I21)*0.0215 -> 0 | J31: =(J19+J21)*0.0215 -> 0 | K31: =(K19+K21)*0.0215 -> 0 | L31: =(L19+L21)*0.0215 -> 0 | M31: =(M19+M21)*0.0215 -> 0 | N31: =(N19+N21)*0.0215 -> 0
C33: Concrete for cast-in-situ piles, under reams and sockets:
A35: 7 | C35: Compressive Strength 30Mpa/19mm
C37: Piles | D37: m3 | E37: =SUM(I37:N37) -> 0 | F37: 3500 | G37: =+E37*F37 -> 0 | I37: =((I19+I21)*0.292)+(I14*0.75) -> 0 | J37: =((J19+J21)*0.292)+(J14*0.75) -> 0 | K37: =((K19+K21)*0.292)+(K14*0.75) -> 0 | L37: =((L19+L21)*0.292)+(L14*0.75) -> 0 | M37: =((M19+M21)*0.292)+(M14*0.75) -> 0 | N37: =((N19+N21)*0.292)+(N14*0.75) -> 0
B39: PSF 8.2.20 | C39: Strip / cut heads off:
A41: 8 | C41: 610mm diameter bored pile | D41: No | E41: =SUM(I41:N41) -> 0 | F41: 875 | G41: =+E41*F41 -> 0 | I41: =I14 -> 0 | J41: =J14 -> 0 | K41: =K14 -> 0 | L41: =L14 -> 0 | M41: =M14 -> 0 | N41: =N14 -> 0
B43: SANS 1200D | C43: EARTHWORKS
A45: 9 | B45: 8.3.3 | C45: Rip and scarify in-situ material for a depth of 150mm, breaking down oversize material, adding suitable material where necessary and compact to 93% Mod AASHTO density | D45: m2 | E45: =SUM(I45:N45) -> 165 | F45: 225 | G45: =+E45*F45 -> 37125 | J45: 165
A48: CARRIED FORWARD | G48: =SUM(G8:G47) -> 37125
A51: ITEM NO | B51: PAY REF | C51: DESCRIPTION | D51: UNIT | E51: QTY | F51: RATE | G51: AMOUNT
A52: BROUGHT FORWARD | G52: =+G48 -> 37125
B54: 1200D | C54: EARTHWORKS
B56: 8.3.3 | C56: Restricted excavation
C58: Excavation for restricted foundations in all materials and dispose spoil material at a site provided by the Contractor
A60: 10 | C60: Depth up to 2m | D60: m3 | E60: =SUM(I60:N60) -> 50 | F60: 175 | G60: =+E60*F60 -> 8750 | I60: 50
C62: Extra overs on Item above for:
A64: 11 | C64: Soilcrete backfill under structures as indicated on the drawings or directed by the Engineer | D64: m3 | E64: =SUM(I64:N64) -> 0 | F64: 950 | G64: =+E64*F64 -> 0 | I64: 0
C66: (The aggregate of soilcrete shall be mixed with 5% cement of volume and shall consist of approved soil or gravel containing stones, obtained from commercial sources, not bigger than 38mm and with a plasticity index not exceeding 10)
B68: 8.3.4 | C68: Importing of materials
C70: Extra over item for importation of materials from commercial sources:
A72: 12 | C72: Backfill with G5 material compacted to 93% MOD AASHTO from commercial sources selected by the Contractor | D72: m3 | E72: =SUM(I72:N72) -> 26 | F72: 725 | G72: =+E72*F72 -> 18850 | I72: 26
...

Sheet Workshop
A1: GEORGE BIOMASS POWER PLANT
A2: =Summary!A2 -> NAFASI WATER - ARNOT WASTE TREATMENT PLANT | G2: =Summary!C2 -> Revision T1
A3: =Summary!A3 -> PILING AND CIVIL WORK
A4: SECTION 4 - BILL OF QUANTITIES | G4: =Summary!C4 -> 45183
A6: ITEM NO | B6: PAY REF | C6: DESCRIPTION | D6: UNIT | E6: QTY | F6: RATE | G6: AMOUNT | I6: Foundations | J6: Surface Beds | K6: Building Works
C8: WORKSHOP BUILDING
B10: SANS 1200F | C10: PILING (BORED PILES) | E10: =IF(SUM(H10:M10)>0,SUM(H10:M10),"")
E11: =IF(SUM(H11:M11)>0,SUM(H11:M11),"")
C12: Move equipment and setup: | E12: =IF(SUM(H12:M12)>0,SUM(H12:M12),"")
E13: =IF(SUM(H13:M13)>0,SUM(H13:M13),"")
A14: 1 | C14: Move equipment to and set up each pile position for heavy bored cast-in-situ piles (610mm diameter) | D14: No | E14: =SUM(I14:N14) -> 0 | F14: 1150 | G14: =+E14*F14 -> 0 | I14: 0 | J14: 0 | K14: 0 | L14: 0 | M14: 0 | N14: 0
C16: Bore Holes for Piles:
C17: Bored holes for cast-in-situ piles of 610mm diameter (heavy) through material situated in the following successive depth ranges:
A19: 2 | C19: 0m up to 10m | D19: m | E19: =SUM(I19:N19) -> 0 | F19: 1850 | G19: =+E19*F19 -> 0 | I19: =I14*10 -> 0 | J19: =J14*10 -> 0 | K19: =K14*10 -> 0 | L19: =L14*10 -> 0 | M19: =M14*10 -> 0 | N19: =N14*10 -> 0
A21: 3 | C21: 10m up to 20m | D21: m | E21: =SUM(I21:N21) -> 0 | F21: =F19 -> 1850 | G21: =+E21*F21 -> 0 | I21: =I14*5 -> 0 | J21: =J14*5 -> 0 | K21: =K14*5 -> 0 | L21: =L14*5 -> 0 | M21: =M14*5 -> 0 | N21: =N14*5 -> 0
C23: Forming of Bulbous bases:
A25: 4 | C25: For DCS piles of 610mm diameter | D25: No | E25: =SUM(I25:N25) -> 0 | F25: 1250 | G25: =+E25*F25 -> 0 | I25: =I14 -> 0 | J25: =J14 -> 0 | K25: =K14 -> 0 | L25: =L14 -> 0 | M25: =M14 -> 0 | N25: =N14 -> 0
C27: Steel reinforcement in cast-in-situ piles:
A29: 5 | C29: Mild steel, Plain | D29: t | E29: =SUM(I29:N29) -> 0 | F29: 29500 | G29: =+E29*F29 -> 0 | I29: =(I19+I21)*0.00325 -> 0 | J29: =(J19+J21)*0.00325 -> 0 | K29: =(K19+K21)*0.00325 -> 0 | L29: =(L19+L21)*0.00325 -> 0 | M29: =(M19+M21)*0.00325 -> 0 | N29: =(N19+N21)*0.00325 -> 0
A31: 6 | C31: High yield stress steel | D31: t | E31: =SUM(I31:AG31) -> 0 | F31: 28000 | G31: =+E31*F31 -> 0 | I31: =(I19+I21)*0.0215 -> 0 | J31: =(J19+J21)*0.0215 -> 0 | K31: =(K19+K21)*0.0215 -> 0 | L31: =(L19+L21)*0.0215 -> 0 | M31: =(M19+M21)*0.0215 -> 0 | N31: =(N19+N21)*0.0215 -> 0
C33: Concrete for cast-in-situ piles, under reams and sockets:
A35: 7 | C35: Compressive Strength 30Mpa/19mm
C37: Piles | D37: m3 | E37: =SUM(I37:N37) -> 0 | F37: 3500 | G37: =+E37*F37 -> 0 | I37: =((I19+I21)*0.292)+(I14*0.75) -> 0 | J37: =((J19+J21)*0.292)+(J14*0.75) -> 0 | K37: =((K19+K21)*0.292)+(K14*0.75) -> 0 | L37: =((L19+L21)*0.292)+(L14*0.75) -> 0 | M37: =((M19+M21)*0.292)+(M14*0.75) -> 0 | N37: =((N19+N21)*0.292)+(N14*0.75) -> 0
B39: PSF 8.2.20 | C39: Strip / cut heads off:
A41: 8 | C41: 610mm diameter bored pile | D41: No | E41: =SUM(I41:N41) -> 0 | F41: 875 | G41: =+E41*F41 -> 0 | I41: =I14 -> 0 | J41: =J14 -> 0 | K41: =K14 -> 0 | L41: =L14 -> 0 | M41: =M14 -> 0 | N41: =N14 -> 0
B43: SANS 1200D | C43: EARTHWORKS
A45: 9 | B45: 8.3.3 | C45: Rip and scarify in-situ material for a depth of 150mm, breaking down oversize material, adding suitable material where necessary and compact to 93% Mod AASHTO density | D45: m2 | E45: =SUM(I45:N45) -> 220 | F45: 225 | G45: =+E45*F45 -> 49500 | J45: 220
A48: CARRIED FORWARD | G48: =SUM(G8:G47) -> 49500
A51: ITEM NO | B51: PAY REF | C51: DESCRIPTION | D51: UNIT | E51: QTY | F51: RATE | G51: AMOUNT
A52: BROUGHT FORWARD | G52: =+G48 -> 49500
B54: 1200D | C54: EARTHWORKS
B56: 8.3.3 | C56: Restricted excavation
C58: Excavation for restricted foundations in all materials and dispose spoil material at a site provided by the Contractor
A60: 10 | C60: Depth up to 2m | D60: m3 | E60: =SUM(I60:N60) -> 61 | F60: 175 | G60: =+E60*F60 -> 10675 | I60: 61
C62: Extra overs on Item above for:
A64: 11 | C64: Soilcrete backfill under structures as indicated on the drawings or directed by the Engineer | D64: m3 | E64: =SUM(I64:N64) -> 0 | F64: 950 | G64: =+E64*F64 -> 0
C66: (The aggregate of soilcrete shall be mixed with 5% cement of volume and shall consist of approved soil or gravel containing stones, obtained from commercial sources, not bigger than 38mm and with a plasticity index not exceeding 10)
B68: 8.3.4 | C68: Importing of materials
C70: Extra over item for importation of materials from commercial sources:
A72: 12 | C72: Backfill with G5 material compacted to 93% MOD AASHTO from commercial sources selected by the Contractor | D72: m3 | E72: =SUM(I72:N72) -> 31 | F72: 725 | G72: =+E72*F72 -> 22475 | I72: 31
...

Sheet MCC2 Foundations
A1: GEORGE BIOMASS POWER PLANT
A2: =Summary!A2 -> NAFASI WATER - ARNOT WASTE TREATMENT PLANT | G2: =Summary!C2 -> Revision T1
A3: =Summary!A3 -> PILING AND CIVIL WORK
A4: SECTION 5 - BILL OF QUANTITIES | G4: =Summary!C4 -> 45183
A6: ITEM NO | B6: PAY REF | C6: DESCRIPTION | D6: UNIT | E6: QTY | F6: RATE | G6: AMOUNT | I6: Foundations
C8: MCC 2 BUILDING FOUNDATIONS
B10: SANS 1200F | C10: PILING (BORED PILES) | E10: =IF(SUM(H10:M10)>0,SUM(H10:M10),"")
E11: =IF(SUM(H11:M11)>0,SUM(H11:M11),"")
C12: Move equipment and setup: | E12: =IF(SUM(H12:M12)>0,SUM(H12:M12),"")
E13: =IF(SUM(H13:M13)>0,SUM(H13:M13),"")
A14: 1 | C14: Move equipment to and set up each pile position for heavy bored cast-in-situ piles (610mm diameter) | D14: No | E14: =SUM(I14:N14) -> 0 | F14: 1150 | G14: =+E14*F14 -> 0 | I14: 0 | J14: 0 | K14: 0 | L14: 0 | M14: 0 | N14: 0
C16: Bore Holes for Piles:
C17: Bored holes for cast-in-situ piles of 610mm diameter (heavy) through material situated in the following successive depth ranges:
A19: 2 | C19: 0m up to 10m | D19: m | E19: =SUM(I19:N19) -> 0 | F19: 1850 | G19: =+E19*F19 -> 0 | I19: =I14*10 -> 0 | J19: =J14*10 -> 0 | K19: =K14*10 -> 0 | L19: =L14*10 -> 0 | M19: =M14*10 -> 0 | N19: =N14*10 -> 0
A21: 3 | C21: 10m up to 20m | D21: m | E21: =SUM(I21:N21) -> 0 | F21: =F19 -> 1850 | G21: =+E21*F21 -> 0 | I21: =I14*5 -> 0 | J21: =J14*5 -> 0 | K21: =K14*5 -> 0 | L21: =L14*5 -> 0 | M21: =M14*5 -> 0 | N21: =N14*5 -> 0
C23: Forming of Bulbous bases:
A25: 4 | C25: For DCS piles of 610mm diameter | D25: No | E25: =SUM(I25:N25) -> 0 | F25: 1250 | G25: =+E25*F25 -> 0 | I25: =I14 -> 0 | J25: =J14 -> 0 | K25: =K14 -> 0 | L25: =L14 -> 0 | M25: =M14 -> 0 | N25: =N14 -> 0
C27: Steel reinforcement in cast-in-situ piles:
A29: 5 | C29: Mild steel, Plain | D29: t | E29: =SUM(I29:N29) -> 0 | F29: 29500 | G29: =+E29*F29 -> 0 | I29: =(I19+I21)*0.00325 -> 0 | J29: =(J19+J21)*0.00325 -> 0 | K29: =(K19+K21)*0.00325 -> 0 | L29: =(L19+L21)*0.00325 -> 0 | M29: =(M19+M21)*0.00325 -> 0 | N29: =(N19+N21)*0.00325 -> 0
A31: 6 | C31: High yield stress steel | D31: t | E31: =SUM(I31:AG31) -> 0 | F31: 28000 | G31: =+E31*F31 -> 0 | I31: =(I19+I21)*0.0215 -> 0 | J31: =(J19+J21)*0.0215 -> 0 | K31: =(K19+K21)*0.0215 -> 0 | L31: =(L19+L21)*0.0215 -> 0 | M31: =(M19+M21)*0.0215 -> 0 | N31: =(N19+N21)*0.0215 -> 0
C33: Concrete for cast-in-situ piles, under reams and sockets:
A35: 7 | C35: Compressive Strength 30Mpa/19mm
C37: Piles | D37: m3 | E37: =SUM(I37:N37) -> 0 | F37: 3500 | G37: =+E37*F37 -> 0 | I37: =((I19+I21)*0.292)+(I14*0.75) -> 0 | J37: =((J19+J21)*0.292)+(J14*0.75) -> 0 | K37: =((K19+K21)*0.292)+(K14*0.75) -> 0 | L37: =((L19+L21)*0.292)+(L14*0.75) -> 0 | M37: =((M19+M21)*0.292)+(M14*0.75) -> 0 | N37: =((N19+N21)*0.292)+(N14*0.75) -> 0
B39: PSF 8.2.20 | C39: Strip / cut heads off:
A41: 8 | C41: 610mm diameter bored pile | D41: No | E41: =SUM(I41:N41) -> 0 | F41: 875 | G41: =+E41*F41 -> 0 | I41: =I14 -> 0 | J41: =J14 -> 0 | K41: =K14 -> 0 | L41: =L14 -> 0 | M41: =M14 -> 0 | N41: =N14 -> 0
B43: SANS 1200D | C43: EARTHWORKS
A45: 9 | B45: 8.3.3 | C45: Rip and scarify in-situ material for a depth of 150mm, breaking down oversize material, adding suitable material where necessary and compact to 93% Mod AASHTO density | D45: m2 | E45: =SUM(I45:N45) -> 0 | F45: 225 | G45: =+E45*F45 -> 0
A48: CARRIED FORWARD | G48: =SUM(G8:G47) -> 0
A51: ITEM NO | B51: PAY REF | C51: DESCRIPTION | D51: UNIT | E51: QTY | F51: RATE | G51: AMOUNT
A52: BROUGHT FORWARD | G52: =+G48 -> 0
B54: 1200D | C54: EARTHWORKS
B56: 8.3.3 | C56: Restricted excavation
C58: Excavation for restricted foundations in all materials and dispose spoil material at a site provided by the Contractor
A60: 10 | C60: Depth up to 2m | D60: m3 | E60: =SUM(I60:N60) -> 17 | F60: 175 | G60: =+E60*F60 -> 2975 | I60: 17
C62: Extra overs on Item above for:
A64: 11 | C64: Soilcrete backfill under structures as indicated on the drawings or directed by the Engineer | D64: m3 | E64: =SUM(I64:N64) -> 0 | F64: 950 | G64: =+E64*F64 -> 0
C66: (The aggregate of soilcrete shall be mixed with 5% cement of volume and shall consist of approved soil or gravel containing stones, obtained from commercial sources, not bigger than 38mm and with a plasticity index not exceeding 10)
B68: 8.3.4 | C68: Importing of materials
C70: Extra over item for importation of materials from commercial sources:
A72: 12 | C72: Backfill with G5 material compacted to 93% MOD AASHTO from commercial sources selected by the Contractor | D72: m3 | E72: =SUM(I72:N72) -> 8 | F72: 725 | G72: =+E72*F72 -> 5800 | I72: 8
...

Sheet Ozone Foundations
A1: GEORGE BIOMASS POWER PLANT
A2: =Summary!A2 -> NAFASI WATER - ARNOT WASTE TREATMENT PLANT | G2: =Summary!C2 -> Revision T1
A3: =Summary!A3 -> PILING AND CIVIL WORK
A4: SECTION 6 - BILL OF QUANTITIES | G4: =Summary!C4 -> 45183
A6: ITEM NO | B6: PAY REF | C6: DESCRIPTION | D6: UNIT | E6: QTY | F6: RATE | G6: AMOUNT | I6: Foundations
C8: OZONE BUILDING FOUNDATIONS
B10: SANS 1200F | C10: PILING (BORED PILES) | E10: =IF(SUM(H10:M10)>0,SUM(H10:M10),"")
E11: =IF(SUM(H11:M11)>0,SUM(H11:M11),"")
C12: Move equipment and setup: | E12: =IF(SUM(H12:M12)>0,SUM(H12:M12),"")
E13: =IF(SUM(H13:M13)>0,SUM(H13:M13),"")
A14: 1 | C14: Move equipment to and set up each pile position for heavy bored cast-in-situ piles (610mm diameter) | D14: No | E14: =SUM(I14:N14) -> 0 | F14: 1150 | G14: =+E14*F14 -> 0 | I14: 0 | J14: 0 | K14: 0 | L14: 0 | M14: 0 | N14: 0
C16: Bore Holes for Piles:
C17: Bored holes for cast-in-situ piles of 610mm diameter (heavy) through material situated in the following successive depth ranges:
A19: 2 | C19: 0m up to 10m | D19: m | E19: =SUM(I19:N19) -> 0 | F19: 1850 | G19: =+E19*F19 -> 0 | I19: =I14*10 -> 0 | J19: =J14*10 -> 0 | K19: =K14*10 -> 0 | L19: =L14*10 -> 0 | M19: =M14*10 -> 0 | N19: =N14*10 -> 0
A21: 3 | C21: 10m up to 20m | D21: m | E21: =SUM(I21:N21) -> 0 | F21: =F19 -> 1850 | G21: =+E21*F21 -> 0 | I21: =I14*5 -> 0 | J21: =J14*5 -> 0 | K21: =K14*5 -> 0 | L21: =L14*5 -> 0 | M21: =M14*5 -> 0 | N21: =N14*5 -> 0
C23: Forming of Bulbous bases:
A25: 4 | C25: For DCS piles of 610mm diameter | D25: No | E25: =SUM(I25:N25) -> 0 | F25: 1250 | G25: =+E25*F25 -> 0 | I25: =I14 -> 0 | J25: =J14 -> 0 | K25: =K14 -> 0 | L25: =L14 -> 0 | M25: =M14 -> 0 | N25: =N14 -> 0
C27: Steel reinforcement in cast-in-situ piles:
A29: 5 | C29: Mild steel, Plain | D29: t | E29: =SUM(I29:N29) -> 0 | F29: 29500 | G29: =+E29*F29 -> 0 | I29: =(I19+I21)*0.00325 -> 0 | J29: =(J19+J21)*0.00325 -> 0 | K29: =(K19+K21)*0.00325 -> 0 | L29: =(L19+L21)*0.00325 -> 0 | M29: =(M19+M21)*0.00325 -> 0 | N29: =(N19+N21)*0.00325 -> 0
A31: 6 | C31: High yield stress steel | D31: t | E31: =SUM(I31:AG31) -> 0 | F31: 28000 | G31: =+E31*F31 -> 0 | I31: =(I19+I21)*0.0215 -> 0 | J31: =(J19+J21)*0.0215 -> 0 | K31: =(K19+K21)*0.0215 -> 0 | L31: =(L19+L21)*0.0215 -> 0 | M31: =(M19+M21)*0.0215 -> 0 | N31: =(N19+N21)*0.0215 -> 0
C33: Concrete for cast-in-situ piles, under reams and sockets:
A35: 7 | C35: Compressive Strength 30Mpa/19mm
C37: Piles | D37: m3 | E37: =SUM(I37:N37) -> 0 | F37: 3500 | G37: =+E37*F37 -> 0 | I37: =((I19+I21)*0.292)+(I14*0.75) -> 0 | J37: =((J19+J21)*0.292)+(J14*0.75) -> 0 | K37: =((K19+K21)*0.292)+(K14*0.75) -> 0 | L37: =((L19+L21)*0.292)+(L14*0.75) -> 0 | M37: =((M19+M21)*0.292)+(M14*0.75) -> 0 | N37: =((N19+N21)*0.292)+(N14*0.75) -> 0
B39: PSF 8.2.20 | C39: Strip / cut heads off:
A41: 8 | C41: 610mm diameter bored pile | D41: No | E41: =SUM(I41:N41) -> 0 | F41: 875 | G41: =+E41*F41 -> 0 | I41: =I14 -> 0 | J41: =J14 -> 0 | K41: =K14 -> 0 | L41: =L14 -> 0 | M41: =M14 -> 0 | N41: =N14 -> 0
B43: SANS 1200D | C43: EARTHWORKS
A45: 9 | B45: 8.3.3 | C45: Rip and scarify in-situ material for a depth of 150mm, breaking down oversize material, adding suitable material where necessary and compact to 93% Mod AASHTO density | D45: m2 | E45: =SUM(I45:N45) -> 0 | F45: 225 | G45: =+E45*F45 -> 0
A48: CARRIED FORWARD | G48: =SUM(G8:G47) -> 0
A51: ITEM NO | B51: PAY REF | C51: DESCRIPTION | D51: UNIT | E51: QTY | F51: RATE | G51: AMOUNT
A52: BROUGHT FORWARD | G52: =+G48 -> 0
B54: 1200D | C54: EARTHWORKS
B56: 8.3.3 | C56: Restricted excavation
C58: Excavation for restricted foundations in all materials and dispose spoil material at a site provided by the Contractor
A60: 10 | C60: Depth up to 2m | D60: m3 | E60: =SUM(I60:N60) -> 16.6 | F60: 175 | G60: =+E60*F60 -> 2905 | I60: 16.6
C62: Extra overs on Item above for:
A64: 11 | C64: Soilcrete backfill under structures as indicated on the drawings or directed by the Engineer | D64: m3 | E64: =SUM(I64:N64) -> 0 | F64: 950 | G64: =+E64*F64 -> 0
C66: (The aggregate of soilcrete shall be mixed with 5% cement of volume and shall consist of approved soil or gravel containing stones, obtained from commercial sources, not bigger than 38mm and with a plasticity index not exceeding 10)
B68: 8.3.4 | C68: Importing of materials
C70: Extra over item for importation of materials from commercial sources:
A72: 12 | C72: Backfill with G5 material compacted to 93% MOD AASHTO from commercial sources selected by the Contractor | D72: m3 | E72: =SUM(I72:N72) -> 7.6 | F72: 725 | G72: =+E72*F72 -> 5510 | I72: 7.6
...

Sheet Water Tanks Foundations
A1: GEORGE BIOMASS POWER PLANT
A2: =Summary!A2 -> NAFASI WATER - ARNOT WASTE TREATMENT PLANT | G2: =Summary!C2 -> Revision T1
A3: =Summary!A3 -> PILING AND CIVIL WORK
A4: SECTION 7 - BILL OF QUANTITIES | G4: =Summary!C4 -> 45183
A6: ITEM NO | B6: PAY REF | C6: DESCRIPTION | D6: UNIT | E6: QTY | F6: RATE | G6: AMOUNT | I6: Foundations | J6: Surface Beds | K6: Pump Plinths | L6: Sump
C8: WATER TANKS FOUNDATIONS
B10: SANS 1200F | C10: PILING (BORED PILES) | E10: =IF(SUM(H10:M10)>0,SUM(H10:M10),"")
E11: =IF(SUM(H11:M11)>0,SUM(H11:M11),"")
C12: Move equipment and setup: | E12: =IF(SUM(H12:M12)>0,SUM(H12:M12),"")
E13: =IF(SUM(H13:M13)>0,SUM(H13:M13),"")
A14: 1 | C14: Move equipment to and set up each pile position for heavy bored cast-in-situ piles (610mm diameter) | D14: No | E14: =SUM(I14:N14) -> 0 | F14: 1150 | G14: =+E14*F14 -> 0 | I14: 0 | J14: 0 | K14: 0 | L14: 0 | M14: 0 | N14: 0
C16: Bore Holes for Piles:
C17: Bored holes for cast-in-situ piles of 610mm diameter (heavy) through material situated in the following successive depth ranges:
A19: 2 | C19: 0m up to 10m | D19: m | E19: =SUM(I19:N19) -> 0 | F19: 1850 | G19: =+E19*F19 -> 0 | I19: =I14*10 -> 0 | J19: =J14*10 -> 0 | K19: =K14*10 -> 0 | L19: =L14*10 -> 0 | M19: =M14*10 -> 0 | N19: =N14*10 -> 0
A21: 3 | C21: 10m up to 20m | D21: m | E21: =SUM(I21:N21) -> 0 | F21: =F19 -> 1850 | G21: =+E21*F21 -> 0 | I21: =I14*5 -> 0 | J21: =J14*5 -> 0 | K21: =K14*5 -> 0 | L21: =L14*5 -> 0 | M21: =M14*5 -> 0 | N21: =N14*5 -> 0
C23: Forming of Bulbous bases:
A25: 4 | C25: For DCS piles of 610mm diameter | D25: No | E25: =SUM(I25:N25) -> 0 | F25: 1250 | G25: =+E25*F25 -> 0 | I25: =I14 -> 0 | J25: =J14 -> 0 | K25: =K14 -> 0 | L25: =L14 -> 0 | M25: =M14 -> 0 | N25: =N14 -> 0
C27: Steel reinforcement in cast-in-situ piles:
A29: 5 | C29: Mild steel, Plain | D29: t | E29: =SUM(I29:N29) -> 0 | F29: 29500 | G29: =+E29*F29 -> 0 | I29: =(I19+I21)*0.00325 -> 0 | J29: =(J19+J21)*0.00325 -> 0 | K29: =(K19+K21)*0.00325 -> 0 | L29: =(L19+L21)*0.00325 -> 0 | M29: =(M19+M21)*0.00325 -> 0 | N29: =(N19+N21)*0.00325 -> 0
A31: 6 | C31: High yield stress steel | D31: t | E31: =SUM(I31:AG31) -> 0 | F31: 28000 | G31: =+E31*F31 -> 0 | I31: =(I19+I21)*0.0215 -> 0 | J31: =(J19+J21)*0.0215 -> 0 | K31: =(K19+K21)*0.0215 -> 0 | L31: =(L19+L21)*0.0215 -> 0 | M31: =(M19+M21)*0.0215 -> 0 | N31: =(N19+N21)*0.0215 -> 0
C33: Concrete for cast-in-situ piles, under reams and sockets:
A35: 7 | C35: Compressive Strength 30Mpa/19mm
C37: Piles | D37: m3 | E37: =SUM(I37:N37) -> 0 | F37: 3500 | G37: =+E37*F37 -> 0 | I37: =((I19+I21)*0.292)+(I14*0.75) -> 0 | J37: =((J19+J21)*0.292)+(J14*0.75) -> 0 | K37: =((K19+K21)*0.292)+(K14*0.75) -> 0 | L37: =((L19+L21)*0.292)+(L14*0.75) -> 0 | M37: =((M19+M21)*0.292)+(M14*0.75) -> 0 | N37: =((N19+N21)*0.292)+(N14*0.75) -> 0
B39: PSF 8.2.20 | C39: Strip / cut heads off:
A41: 8 | C41: 610mm diameter bored pile | D41: No | E41: =SUM(I41:N41) -> 0 | F41: 875 | G41: =+E41*F41 -> 0 | I41: =I14 -> 0 | J41: =J14 -> 0 | K41: =K14 -> 0 | L41: =L14 -> 0 | M41: =M14 -> 0 | N41: =N14 -> 0
B43: SANS 1200D | C43: EARTHWORKS
A45: 9 | B45: 8.3.3 | C45: Rip and scarify in-situ material for a depth of 150mm, breaking down oversize material, adding suitable material where necessary and compact to 93% Mod AASHTO density | D45: m2 | E45: =SUM(I45:N45) -> 220 | F45: 225 | G45: =+E45*F45 -> 49500 | J45: 220
A48: CARRIED FORWARD | G48: =SUM(G8:G47) -> 49500
A51: ITEM NO | B51: PAY REF | C51: DESCRIPTION | D51: UNIT | E51: QTY | F51: RATE | G51: AMOUNT
A52: BROUGHT FORWARD | G52: =+G48 -> 49500
B54: 1200D | C54: EARTHWORKS
B56: 8.3.3 | C56: Restricted excavation
C58: Excavation for restricted foundations in all materials and dispose spoil material at a site provided by the Contractor
A60: 10 | C60: Depth up to 2m | D60: m3 | E60: =SUM(I60:N60) -> 181.3 | F60: 175 | G60: =+E60*F60 -> 31727.5 | I60: 94.9 | L60: 86.4
C62: Extra overs on Item above for:
A64: 11 | C64: Soilcrete backfill under structures as indicated on the drawings or directed by the Engineer | D64: m3 | E64: =SUM(I64:N64) -> 0 | F64: 950 | G64: =+E64*F64 -> 0
C66: (The aggregate of soilcrete shall be mixed with 5% cement of volume and shall consist of approved soil or gravel containing stones, obtained from commercial sources, not bigger than 38mm and with a plasticity index not exceeding 10)
B68: 8.3.4 | C68: Importing of materials
C70: Extra over item for importation of materials from commercial sources:
A72: 12 | C72: Backfill with G5 material compacted to 93% MOD AASHTO from commercial sources selected by the Contractor | D72: m3 | E72: =SUM(I72:N72) -> 77.68 | F72: 725 | G72: =+E72*F72 -> 56318 | I72: 32.5 | L72: 45.18
...

Sheet Sulpheric Tank Bunded 
A1: GEORGE BIOMASS POWER PLANT
A2: =Summary!A2 -> NAFASI WATER - ARNOT WASTE TREATMENT PLANT | G2: =Summary!C2 -> Revision T1
A3: =Summary!A3 -> PILING AND CIVIL WORK
A4: SECTION 8 - BILL OF QUANTITIES | G4: =Summary!C4 -> 45183
A6: ITEM NO | B6: PAY REF | C6: DESCRIPTION | D6: UNIT | E6: QTY | F6: RATE | G6: AMOUNT | I6: Surface Beds | J6: Retaining Wall | K6: Plinths | L6: Pump Plinths | M6: Sump
C8: SULPHERIC TANKS BUNDED AREA
B10: SANS 1200F | C10: PILING (BORED PILES) | E10: =IF(SUM(H10:M10)>0,SUM(H10:M10),"")
E11: =IF(SUM(H11:M11)>0,SUM(H11:M11),"")
C12: Move equipment and setup: | E12: =IF(SUM(H12:M12)>0,SUM(H12:M12),"")
E13: =IF(SUM(H13:M13)>0,SUM(H13:M13),"")
A14: 1 | C14: Move equipment to and set up each pile position for heavy bored cast-in-situ piles (610mm diameter) | D14: No | E14: =SUM(I14:N14) -> 0 | F14: 1150 | G14: =+E14*F14 -> 0 | I14: 0 | J14: 0 | K14: 0 | L14: 0 | M14: 0 | N14: 0
C16: Bore Holes for Piles:
C17: Bored holes for cast-in-situ piles of 610mm diameter (heavy) through material situated in the following successive depth ranges:
A19: 2 | C19: 0m up to 10m | D19: m | E19: =SUM(I19:N19) -> 0 | F19: 1850 | G19: =+E19*F19 -> 0 | I19: =I14*10 -> 0 | J19: =J14*10 -> 0 | K19: =K14*10 -> 0 | L19: =L14*10 -> 0 | M19: =M14*10 -> 0 | N19: =N14*10 -> 0
A21: 3 | C21: 10m up to 20m | D21: m | E21: =SUM(I21:N21) -> 0 | F21: =F19 -> 1850 | G21: =+E21*F21 -> 0 | I21: =I14*5 -> 0 | J21: =J14*5 -> 0 | K21: =K14*5 -> 0 | L21: =L14*5 -> 0 | M21: =M14*5 -> 0 | N21: =N14*5 -> 0
C23: Forming of Bulbous bases:
A25: 4 | C25: For DCS piles of 610mm diameter | D25: No | E25: =SUM(I25:N25) -> 0 | F25: 1250 | G25: =+E25*F25 -> 0 | I25: =I14 -> 0 | J25: =J14 -> 0 | K25: =K14 -> 0 | L25: =L14 -> 0 | M25: =M14 -> 0 | N25: =N14 -> 0
C27: Steel reinforcement in cast-in-situ piles:
A29: 5 | C29: Mild steel, Plain | D29: t | E29: =SUM(I29:N29) -> 0 | F29: 29500 | G29: =+E29*F29 -> 0 | I29: =(I19+I21)*0.00325 -> 0 | J29: =(J19+J21)*0.00325 -> 0 | K29: =(K19+K21)*0.00325 -> 0 | L29: =(L19+L21)*0.00325 -> 0 | M29: =(M19+M21)*0.00325 -> 0 | N29: =(N19+N21)*0.00325 -> 0
A31: 6 | C31: High yield stress steel | D31: t | E31: =SUM(I31:AG31) -> 0 | F31: 28000 | G31: =+E31*F31 -> 0 | I31: =(I19+I21)*0.0215 -> 0 | J31: =(J19+J21)*0.0215 -> 0 | K31: =(K19+K21)*0.0215 -> 0 | L31: =(L19+L21)*0.0215 -> 0 | M31: =(M19+M21)*0.0215 -> 0 | N31: =(N19+N21)*0.0215 -> 0
C33: Concrete for cast-in-situ piles, under reams and sockets:
A35: 7 | C35: Compressive Strength 30Mpa/19mm
C37: Piles | D37: m3 | E37: =SUM(I37:N37) -> 0 | F37: 3500 | G37: =+E37*F37 -> 0 | I37: =((I19+I21)*0.292)+(I14*0.75) -> 0 | J37: =((J19+J21)*0.292)+(J14*0.75) -> 0 | K37: =((K19+K21)*0.292)+(K14*0.75) -> 0 | L37: =((L19+L21)*0.292)+(L14*0.75) -> 0 | M37: =((M19+M21)*0.292)+(M14*0.75) -> 0 | N37: =((N19+N21)*0.292)+(N14*0.75) -> 0
B39: PSF 8.2.20 | C39: Strip / cut heads off:
A41: 8 | C41: 610mm diameter bored pile | D41: No | E41: =SUM(I41:N41) -> 0 | F41: 875 | G41: =+E41*F41 -> 0 | I41: =I14 -> 0 | J41: =J14 -> 0 | K41: =K14 -> 0 | L41: =L14 -> 0 | M41: =M14 -> 0 | N41: =N14 -> 0
B43: SANS 1200D | C43: EARTHWORKS
A45: 9 | B45: 8.3.3 | C45: Rip and scarify in-situ material for a depth of 150mm, breaking down oversize material, adding suitable material where necessary and compact to 93% Mod AASHTO density | D45: m2 | E45: =SUM(I45:N45) -> 66 | F45: 225 | G45: =+E45*F45 -> 14850 | I45: 66
A48: CARRIED FORWARD | G48: =SUM(G8:G47) -> 14850
A51: ITEM NO | B51: PAY REF | C51: DESCRIPTION | D51: UNIT | E51: QTY | F51: RATE | G51: AMOUNT
A52: BROUGHT FORWARD | G52: =+G48 -> 14850
B54: 1200D | C54: EARTHWORKS
B56: 8.3.3 | C56: Restricted excavation
C58: Excavation for restricted foundations in all materials and dispose spoil material at a site provided by the Contractor
A60: 10 | C60: Depth up to 2m | D60: m3 | E60: =SUM(I60:N60) -> 37.15 | F60: 175 | G60: =+E60*F60 -> 6501.25 | J60: 20 | M60: 17.15
C62: Extra overs on Item above for:
A64: 11 | C64: Soilcrete backfill under structures as indicated on the drawings or directed by the Engineer | D64: m3 | E64: =SUM(I64:N64) -> 0 | F64: 950 | G64: =+E64*F64 -> 0
C66: (The aggregate of soilcrete shall be mixed with 5% cement of volume and shall consist of approved soil or gravel containing stones, obtained from commercial sources, not bigger than 38mm and with a plasticity index not exceeding 10)
B68: 8.3.4 | C68: Importing of materials
C70: Extra over item for importation of materials from commercial sources:
A72: 12 | C72: Backfill with G5 material compacted to 93% MOD AASHTO from commercial sources selected by the Contractor | D72: m3 | E72: =SUM(I72:N72) -> 17.78 | F72: 725 | G72: =+E72*F72 -> 12890.5 | J72: 5 | M72: 12.78
...

Sheet Chemical Dosing Bunded
A1: GEORGE BIOMASS POWER PLANT
A2: =Summary!A2 -> NAFASI WATER - ARNOT WASTE TREATMENT PLANT | G2: =Summary!C2 -> Revision T1
A3: =Summary!A3 -> PILING AND CIVIL WORK
A4: SECTION 9 - BILL OF QUANTITIES | G4: =Summary!C4 -> 45183
A6: ITEM NO | B6: PAY REF | C6: DESCRIPTION | D6: UNIT | E6: QTY | F6: RATE | G6: AMOUNT | I6: Surface Beds | J6: Retaining Wall | K6: Sump
C8: CHEMICAL DOSING BUNDED AREA
B10: SANS 1200F | C10: PILING (BORED PILES) | E10: =IF(SUM(H10:M10)>0,SUM(H10:M10),"")
E11: =IF(SUM(H11:M11)>0,SUM(H11:M11),"")
C12: Move equipment and setup: | E12: =IF(SUM(H12:M12)>0,SUM(H12:M12),"")
E13: =IF(SUM(H13:M13)>0,SUM(H13:M13),"")
A14: 1 | C14: Move equipment to and set up each pile position for heavy bored cast-in-situ piles (610mm diameter) | D14: No | E14: =SUM(I14:N14) -> 0 | F14: 1150 | G14: =+E14*F14 -> 0 | I14: 0 | J14: 0 | K14: 0 | L14: 0 | M14: 0 | N14: 0
C16: Bore Holes for Piles:
C17: Bored holes for cast-in-situ piles of 610mm diameter (heavy) through material situated in the following successive depth ranges:
A19: 2 | C19: 0m up to 10m | D19: m | E19: =SUM(I19:N19) -> 0 | F19: 1850 | G19: =+E19*F19 -> 0 | I19: =I14*10 -> 0 | J19: =J14*10 -> 0 | K19: =K14*10 -> 0 | L19: =L14*10 -> 0 | M19: =M14*10 -> 0 | N19: =N14*10 -> 0
A21: 3 | C21: 10m up to 20m | D21: m | E21: =SUM(I21:N21) -> 0 | F21: =F19 -> 1850 | G21: =+E21*F21 -> 0 | I21: =I14*5 -> 0 | J21: =J14*5 -> 0 | K21: =K14*5 -> 0 | L21: =L14*5 -> 0 | M21: =M14*5 -> 0 | N21: =N14*5 -> 0
C23: Forming of Bulbous bases:
A25: 4 | C25: For DCS piles of 610mm diameter | D25: No | E25: =SUM(I25:N25) -> 0 | F25: 1250 | G25: =+E25*F25 -> 0 | I25: =I14 -> 0 | J25: =J14 -> 0 | K25: =K14 -> 0 | L25: =L14 -> 0 | M25: =M14 -> 0 | N25: =N14 -> 0
C27: Steel reinforcement in cast-in-situ piles:
A29: 5 | C29: Mild steel, Plain | D29: t | E29: =SUM(I29:N29) -> 0 | F29: 29500 | G29: =+E29*F29 -> 0 | I29: =(I19+I21)*0.00325 -> 0 | J29: =(J19+J21)*0.00325 -> 0 | K29: =(K19+K21)*0.00325 -> 0 | L29: =(L19+L21)*0.00325 -> 0 | M29: =(M19+M21)*0.00325 -> 0 | N29: =(N19+N21)*0.00325 -> 0
A31: 6 | C31: High yield stress steel | D31: t | E31: =SUM(I31:AG31) -> 0 | F31: 28000 | G31: =+E31*F31 -> 0 | I31: =(I19+I21)*0.0215 -> 0 | J31: =(J19+J21)*0.0215 -> 0 | K31: =(K19+K21)*0.0215 -> 0 | L31: =(L19+L21)*0.0215 -> 0 | M31: =(M19+M21)*0.0215 -> 0 | N31: =(N19+N21)*0.0215 -> 0
C33: Concrete for cast-in-situ piles, under reams and sockets:
A35: 7 | C35: Compressive Strength 30Mpa/19mm
C37: Piles | D37: m3 | E37: =SUM(I37:N37) -> 0 | F37: 3500 | G37: =+E37*F37 -> 0 | I37: =((I19+I21)*0.292)+(I14*0.75) -> 0 | J37: =((J19+J21)*0.292)+(J14*0.75) -> 0 | K37: =((K19+K21)*0.292)+(K14*0.75) -> 0 | L37: =((L19+L21)*0.292)+(L14*0.75) -> 0 | M37: =((M19+M21)*0.292)+(M14*0.75) -> 0 | N37: =((N19+N21)*0.292)+(N14*0.75) -> 0
B39: PSF 8.2.20 | C39: Strip / cut heads off:
A41: 8 | C41: 610mm diameter bored pile | D41: No | E41: =SUM(I41:N41) -> 0 | F41: 875 | G41: =+E41*F41 -> 0 | I41: =I14 -> 0 | J41: =J14 -> 0 | K41: =K14 -> 0 | L41: =L14 -> 0 | M41: =M14 -> 0 | N41: =N14 -> 0
B43: SANS 1200D | C43: EARTHWORKS
A45: 9 | B45: 8.3.3 | C45: Rip and scarify in-situ material for a depth of 150mm, breaking down oversize material, adding suitable material where necessary and compact to 93% Mod AASHTO density | D45: m2 | E45: =SUM(I45:N45) -> 110 | F45: 225 | G45: =+E45*F45 -> 24750 | I45: 110
A48: CARRIED FORWARD | G48: =SUM(G8:G47) -> 24750
A51: ITEM NO | B51: PAY REF | C51: DESCRIPTION | D51: UNIT | E51: QTY | F51: RATE | G51: AMOUNT
A52: BROUGHT FORWARD | G52: =+G48 -> 24750
B54: 1200D | C54: EARTHWORKS
B56: 8.3.3 | C56: Restricted excavation
C58: Excavation for restricted foundations in all materials and dispose spoil material at a site provided by the Contractor
A60: 10 | C60: Depth up to 2m | D60: m3 | E60: =SUM(I60:N60) -> 148.15 | F60: 175 | G60: =+E60*F60 -> 25926.25 | J60: 131 | K60: 17.15
C62: Extra overs on Item above for:
A64: 11 | C64: Soilcrete backfill under structures as indicated on the drawings or directed by the Engineer | D64: m3 | E64: =SUM(I64:N64) -> 0 | F64: 950 | G64: =+E64*F64 -> 0
C66: (The aggregate of soilcrete shall be mixed with 5% cement of volume and shall consist of approved soil or gravel containing stones, obtained from commercial sources, not bigger than 38mm and with a plasticity index not exceeding 10)
B68: 8.3.4 | C68: Importing of materials
C70: Extra over item for importation of materials from commercial sources:
A72: 12 | C72: Backfill with G5 material compacted to 93% MOD AASHTO from commercial sources selected by the Contractor | D72: m3 | E72: =SUM(I72:N72) -> 105.78 | F72: 725 | G72: =+E72*F72 -> 76690.5 | J72: 93 | K72: 12.78
...

Sheet S1 Tank Bunded 
A1: GEORGE BIOMASS POWER PLANT
A2: =Summary!A2 -> NAFASI WATER - ARNOT WASTE TREATMENT PLANT | G2: =Summary!C2 -> Revision T1
A3: =Summary!A3 -> PILING AND CIVIL WORK
A4: SECTION 10 - BILL OF QUANTITIES | G4: =Summary!C4 -> 45183
A6: ITEM NO | B6: PAY REF | C6: DESCRIPTION | D6: UNIT | E6: QTY | F6: RATE | G6: AMOUNT | I6: Surface Beds | J6: Retaining Wall | K6: Tank Plints | L6: Sump | M6: Pump Plints
C8: S1 TANK BUNDED AREA
B10: SANS 1200F | C10: PILING (BORED PILES) | E10: =IF(SUM(H10:M10)>0,SUM(H10:M10),"")
E11: =IF(SUM(H11:M11)>0,SUM(H11:M11),"")
C12: Move equipment and setup: | E12: =IF(SUM(H12:M12)>0,SUM(H12:M12),"")
E13: =IF(SUM(H13:M13)>0,SUM(H13:M13),"")
A14: 1 | C14: Move equipment to and set up each pile position for heavy bored cast-in-situ piles (610mm diameter) | D14: No | E14: =SUM(I14:N14) -> 0 | F14: 1150 | G14: =+E14*F14 -> 0 | I14: 0 | J14: 0 | K14: 0 | L14: 0 | M14: 0 | N14: 0
C16: Bore Holes for Piles:
C17: Bored holes for cast-in-situ piles of 610mm diameter (heavy) through material situated in the following successive depth ranges:
A19: 2 | C19: 0m up to 10m | D19: m | E19: =SUM(I19:N19) -> 0 | F19: 1850 | G19: =+E19*F19 -> 0 | I19: =I14*10 -> 0 | J19: =J14*10 -> 0 | K19: =K14*10 -> 0 | L19: =L14*10 -> 0 | M19: =M14*10 -> 0 | N19: =N14*10 -> 0
A21: 3 | C21: 10m up to 20m | D21: m | E21: =SUM(I21:N21) -> 0 | F21: =F19 -> 1850 | G21: =+E21*F21 -> 0 | I21: =I14*5 -> 0 | J21: =J14*5 -> 0 | K21: =K14*5 -> 0 | L21: =L14*5 -> 0 | M21: =M14*5 -> 0 | N21: =N14*5 -> 0
C23: Forming of Bulbous bases:
A25: 4 | C25: For DCS piles of 610mm diameter | D25: No | E25: =SUM(I25:N25) -> 0 | F25: 1250 | G25: =+E25*F25 -> 0 | I25: =I14 -> 0 | J25: =J14 -> 0 | K25: =K14 -> 0 | L25: =L14 -> 0 | M25: =M14 -> 0 | N25: =N14 -> 0
C27: Steel reinforcement in cast-in-situ piles:
A29: 5 | C29: Mild steel, Plain | D29: t | E29: =SUM(I29:N29) -> 0 | F29: 29500 | G29: =+E29*F29 -> 0 | I29: =(I19+I21)*0.00325 -> 0 | J29: =(J19+J21)*0.00325 -> 0 | K29: =(K19+K21)*0.00325 -> 0 | L29: =(L19+L21)*0.00325 -> 0 | M29: =(M19+M21)*0.00325 -> 0 | N29: =(N19+N21)*0.00325 -> 0
A31: 6 | C31: High yield stress steel | D31: t | E31: =SUM(I31:AG31) -> 0 | F31: 28000 | G31: =+E31*F31 -> 0 | I31: =(I19+I21)*0.0215 -> 0 | J31: =(J19+J21)*0.0215 -> 0 | K31: =(K19+K21)*0.0215 -> 0 | L31: =(L19+L21)*0.0215 -> 0 | M31: =(M19+M21)*0.0215 -> 0 | N31: =(N19+N21)*0.0215 -> 0
C33: Concrete for cast-in-situ piles, under reams and sockets:
A35: 7 | C35: Compressive Strength 30Mpa/19mm
C37: Piles | D37: m3 | E37: =SUM(I37:N37) -> 0 | F37: 3500 | G37: =+E37*F37 -> 0 | I37: =((I19+I21)*0.292)+(I14*0.75) -> 0 | J37: =((J19+J21)*0.292)+(J14*0.75) -> 0 | K37: =((K19+K21)*0.292)+(K14*0.75) -> 0 | L37: =((L19+L21)*0.292)+(L14*0.75) -> 0 | M37: =((M19+M21)*0.292)+(M14*0.75) -> 0 | N37: =((N19+N21)*0.292)+(N14*0.75) -> 0
B39: PSF 8.2.20 | C39: Strip / cut heads off:
A41: 8 | C41: 610mm diameter bored pile | D41: No | E41: =SUM(I41:N41) -> 0 | F41: 875 | G41: =+E41*F41 -> 0 | I41: =I14 -> 0 | J41: =J14 -> 0 | K41: =K14 -> 0 | L41: =L14 -> 0 | M41: =M14 -> 0 | N41: =N14 -> 0
B43: SANS 1200D | C43: EARTHWORKS
A45: 9 | B45: 8.3.3 | C45: Rip and scarify in-situ material for a depth of 150mm, breaking down oversize material, adding suitable material where necessary and compact to 93% Mod AASHTO density | D45: m2 | E45: =SUM(I45:N45) -> 169 | F45: 225 | G45: =+E45*F45 -> 38025 | I45: 169
A48: CARRIED FORWARD | G48: =SUM(G8:G47) -> 38025
A51: ITEM NO | B51: PAY REF | C51: DESCRIPTION | D51: UNIT | E51: QTY | F51: RATE | G51: AMOUNT
A52: BROUGHT FORWARD | G52: =+G48 -> 38025
B54: 1200D | C54: EARTHWORKS
B56: 8.3.3 | C56: Restricted excavation
C58: Excavation for restricted foundations in all materials and dispose spoil material at a site provided by the Contractor
A60: 10 | C60: Depth up to 2m | D60: m3 | E60: =SUM(I60:N60) -> 86.15 | F60: 175 | G60: =+E60*F60 -> 15076.25 | J60: 69 | L60: 17.15
C62: Extra overs on Item above for:
A64: 11 | C64: Soilcrete backfill under structures as indicated on the drawings or directed by the Engineer | D64: m3 | E64: =SUM(I64:N64) -> 0 | F64: 950 | G64: =+E64*F64 -> 0
C66: (The aggregate of soilcrete shall be mixed with 5% cement of volume and shall consist of approved soil or gravel containing stones, obtained from commercial sources, not bigger than 38mm and with a plasticity index not exceeding 10)
B68: 8.3.4 | C68: Importing of materials
C70: Extra over item for importation of materials from commercial sources:
A72: 12 | C72: Backfill with G5 material compacted to 93% MOD AASHTO from commercial sources selected by the Contractor | D72: m3 | E72: =SUM(I72:N72) -> 61.78 | F72: 725 | G72: =+E72*F72 -> 44790.5 | J72: 49 | L72: 12.78
...

Sheet Lime System Bunded
A1: GEORGE BIOMASS POWER PLANT
A2: =Summary!A2 -> NAFASI WATER - ARNOT WASTE TREATMENT PLANT | G2: =Summary!C2 -> Revision T1
A3: =Summary!A3 -> PILING AND CIVIL WORK
A4: SECTION 11 - BILL OF QUANTITIES | G4: =Summary!C4 -> 45183
A6: ITEM NO | B6: PAY REF | C6: DESCRIPTION | D6: UNIT | E6: QTY | F6: RATE | G6: AMOUNT | I6: Surface Beds | J6: Retaining Wall | K6: Tank Plints | L6: Sump | M6: Pump Plints | N6: Foundations
C8: LIME SYSTEM BUNDED AREA
B10: SANS 1200F | C10: PILING (BORED PILES) | E10: =IF(SUM(H10:M10)>0,SUM(H10:M10),"")
E11: =IF(SUM(H11:M11)>0,SUM(H11:M11),"")
C12: Move equipment and setup: | E12: =IF(SUM(H12:M12)>0,SUM(H12:M12),"")
E13: =IF(SUM(H13:M13)>0,SUM(H13:M13),"")
A14: 1 | C14: Move equipment to and set up each pile position for heavy bored cast-in-situ piles (610mm diameter) | D14: No | E14: =SUM(I14:N14) -> 4 | F14: 1150 | G14: =+E14*F14 -> 4600 | I14: 0 | J14: 0 | K14: 0 | L14: 0 | M14: 0 | N14: 4
C16: Bore Holes for Piles:
C17: Bored holes for cast-in-situ piles of 610mm diameter (heavy) through material situated in the following successive depth ranges:
A19: 2 | C19: 0m up to 10m | D19: m | E19: =SUM(I19:N19) -> 40 | F19: 1850 | G19: =+E19*F19 -> 74000 | I19: =I14*10 -> 0 | J19: =J14*10 -> 0 | K19: =K14*10 -> 0 | L19: =L14*10 -> 0 | M19: =M14*10 -> 0 | N19: =N14*10 -> 40
A21: 3 | C21: 10m up to 20m | D21: m | E21: =SUM(I21:N21) -> 20 | F21: =F19 -> 1850 | G21: =+E21*F21 -> 37000 | I21: =I14*5 -> 0 | J21: =J14*5 -> 0 | K21: =K14*5 -> 0 | L21: =L14*5 -> 0 | M21: =M14*5 -> 0 | N21: =N14*5 -> 20
C23: Forming of Bulbous bases:
A25: 4 | C25: For DCS piles of 610mm diameter | D25: No | E25: =SUM(I25:N25) -> 4 | F25: 1250 | G25: =+E25*F25 -> 5000 | I25: =I14 -> 0 | J25: =J14 -> 0 | K25: =K14 -> 0 | L25: =L14 -> 0 | M25: =M14 -> 0 | N25: =N14 -> 4
C27: Steel reinforcement in cast-in-situ piles:
A29: 5 | C29: Mild steel, Plain | D29: t | E29: =SUM(I29:N29) -> 0.195 | F29: 29500 | G29: =+E29*F29 -> 5752.5 | I29: =(I19+I21)*0.00325 -> 0 | J29: =(J19+J21)*0.00325 -> 0 | K29: =(K19+K21)*0.00325 -> 0 | L29: =(L19+L21)*0.00325 -> 0 | M29: =(M19+M21)*0.00325 -> 0 | N29: =(N19+N21)*0.00325 -> 0.195
A31: 6 | C31: High yield stress steel | D31: t | E31: =SUM(I31:AG31) -> 1.29 | F31: 28000 | G31: =+E31*F31 -> 36120 | I31: =(I19+I21)*0.0215 -> 0 | J31: =(J19+J21)*0.0215 -> 0 | K31: =(K19+K21)*0.0215 -> 0 | L31: =(L19+L21)*0.0215 -> 0 | M31: =(M19+M21)*0.0215 -> 0 | N31: =(N19+N21)*0.0215 -> 1.29
C33: Concrete for cast-in-situ piles, under reams and sockets:
A35: 7 | C35: Compressive Strength 30Mpa/19mm
C37: Piles | D37: m3 | E37: =SUM(I37:N37) -> 20.52 | F37: 3500 | G37: =+E37*F37 -> 71820 | I37: =((I19+I21)*0.292)+(I14*0.75) -> 0 | J37: =((J19+J21)*0.292)+(J14*0.75) -> 0 | K37: =((K19+K21)*0.292)+(K14*0.75) -> 0 | L37: =((L19+L21)*0.292)+(L14*0.75) -> 0 | M37: =((M19+M21)*0.292)+(M14*0.75) -> 0 | N37: =((N19+N21)*0.292)+(N14*0.75) -> 20.52
B39: PSF 8.2.20 | C39: Strip / cut heads off:
A41: 8 | C41: 610mm diameter bored pile | D41: No | E41: =SUM(I41:N41) -> 4 | F41: 875 | G41: =+E41*F41 -> 3500 | I41: =I14 -> 0 | J41: =J14 -> 0 | K41: =K14 -> 0 | L41: =L14 -> 0 | M41: =M14 -> 0 | N41: =N14 -> 4
B43: SANS 1200D | C43: EARTHWORKS
A45: 9 | B45: 8.3.3 | C45: Rip and scarify in-situ material for a depth of 150mm, breaking down oversize material, adding suitable material where necessary and compact to 93% Mod AASHTO density | D45: m2 | E45: =SUM(I45:N45) -> 59 | F45: 225 | G45: =+E45*F45 -> 13275 | I45: 59
A48: CARRIED FORWARD | G48: =SUM(G8:G47) -> 251067.5
A51: ITEM NO | B51: PAY REF | C51: DESCRIPTION | D51: UNIT | E51: QTY | F51: RATE | G51: AMOUNT
A52: BROUGHT FORWARD | G52: =+G48 -> 251067.5
B54: 1200D | C54: EARTHWORKS
B56: 8.3.3 | C56: Restricted excavation
C58: Excavation for restricted foundations in all materials and dispose spoil material at a site provided by the Contractor
A60: 10 | C60: Depth up to 2m | D60: m3 | E60: =SUM(I60:N60) -> 47.15 | F60: 175 | G60: =+E60*F60 -> 8251.25 | J60: 30 | L60: 17.15
C62: Extra overs on Item above for:
A64: 11 | C64: Soilcrete backfill under structures as indicated on the drawings or directed by the Engineer | D64: m3 | E64: =SUM(I64:N64) -> 0 | F64: 950 | G64: =+E64*F64 -> 0
C66: (The aggregate of soilcrete shall be mixed with 5% cement of volume and shall consist of approved soil or gravel containing stones, obtained from commercial sources, not bigger than 38mm and with a plasticity index not exceeding 10)
B68: 8.3.4 | C68: Importing of materials
C70: Extra over item for importation of materials from commercial sources:
A72: 12 | C72: Backfill with G5 material compacted to 93% MOD AASHTO from commercial sources selected by the Contractor | D72: m3 | E72: =SUM(I72:N72) -> 29.78 | F72: 725 | G72: =+E72*F72 -> 21590.5 | J72: 17 | L72: 12.78
...

Sheet Mixed Slurry Bunded
A1: GEORGE BIOMASS POWER PLANT
A2: =Summary!A2 -> NAFASI WATER - ARNOT WASTE TREATMENT PLANT | G2: =Summary!C2 -> Revision T1
A3: =Summary!A3 -> PILING AND CIVIL WORK
A4: SECTION 12 - BILL OF QUANTITIES | G4: =Summary!C4 -> 45183
A6: ITEM NO | B6: PAY REF | C6: DESCRIPTION | D6: UNIT | E6: QTY | F6: RATE | G6: AMOUNT | I6: Surface Beds | J6: Retaining Wall | K6: Tank Plints | L6: Sump | M6: Pump Plints
C8: MIXED SLURRY BUNDED AREA
B10: SANS 1200F | C10: PILING (BORED PILES) | E10: =IF(SUM(H10:M10)>0,SUM(H10:M10),"")
E11: =IF(SUM(H11:M11)>0,SUM(H11:M11),"")
C12: Move equipment and setup: | E12: =IF(SUM(H12:M12)>0,SUM(H12:M12),"")
E13: =IF(SUM(H13:M13)>0,SUM(H13:M13),"")
A14: 1 | C14: Move equipment to and set up each pile position for heavy bored cast-in-situ piles (610mm diameter) | D14: No | E14: =SUM(I14:N14) -> 0 | F14: 1150 | G14: =+E14*F14 -> 0 | I14: 0 | J14: 0 | K14: 0 | L14: 0 | M14: 0 | N14: 0
C16: Bore Holes for Piles:
C17: Bored holes for cast-in-situ piles of 610mm diameter (heavy) through material situated in the following successive depth ranges:
A19: 2 | C19: 0m up to 10m | D19: m | E19: =SUM(I19:N19) -> 0 | F19: 1850 | G19: =+E19*F19 -> 0 | I19: =I14*10 -> 0 | J19: =J14*10 -> 0 | K19: =K14*10 -> 0 | L19: =L14*10 -> 0 | M19: =M14*10 -> 0 | N19: =N14*10 -> 0
A21: 3 | C21: 10m up to 20m | D21: m | E21: =SUM(I21:N21) -> 0 | F21: =F19 -> 1850 | G21: =+E21*F21 -> 0 | I21: =I14*5 -> 0 | J21: =J14*5 -> 0 | K21: =K14*5 -> 0 | L21: =L14*5 -> 0 | M21: =M14*5 -> 0 | N21: =N14*5 -> 0
C23: Forming of Bulbous bases:
A25: 4 | C25: For DCS piles of 610mm diameter | D25: No | E25: =SUM(I25:N25) -> 0 | F25: 1250 | G25: =+E25*F25 -> 0 | I25: =I14 -> 0 | J25: =J14 -> 0 | K25: =K14 -> 0 | L25: =L14 -> 0 | M25: =M14 -> 0 | N25: =N14 -> 0
C27: Steel reinforcement in cast-in-situ piles:
A29: 5 | C29: Mild steel, Plain | D29: t | E29: =SUM(I29:N29) -> 0 | F29: 29500 | G29: =+E29*F29 -> 0 | I29: =(I19+I21)*0.00325 -> 0 | J29: =(J19+J21)*0.00325 -> 0 | K29: =(K19+K21)*0.00325 -> 0 | L29: =(L19+L21)*0.00325 -> 0 | M29: =(M19+M21)*0.00325 -> 0 | N29: =(N19+N21)*0.00325 -> 0
A31: 6 | C31: High yield stress steel | D31: t | E31: =SUM(I31:AG31) -> 0 | F31: 28000 | G31: =+E31*F31 -> 0 | I31: =(I19+I21)*0.0215 -> 0 | J31: =(J19+J21)*0.0215 -> 0 | K31: =(K19+K21)*0.0215 -> 0 | L31: =(L19+L21)*0.0215 -> 0 | M31: =(M19+M21)*0.0215 -> 0 | N31: =(N19+N21)*0.0215 -> 0
C33: Concrete for cast-in-situ piles, under reams and sockets:
A35: 7 | C35: Compressive Strength 30Mpa/19mm
C37: Piles | D37: m3 | E37: =SUM(I37:N37) -> 0 | F37: 3500 | G37: =+E37*F37 -> 0 | I37: =((I19+I21)*0.292)+(I14*0.75) -> 0 | J37: =((J19+J21)*0.292)+(J14*0.75) -> 0 | K37: =((K19+K21)*0.292)+(K14*0.75) -> 0 | L37: =((L19+L21)*0.292)+(L14*0.75) -> 0 | M37: =((M19+M21)*0.292)+(M14*0.75) -> 0 | N37: =((N19+N21)*0.292)+(N14*0.75) -> 0
B39: PSF 8.2.20 | C39: Strip / cut heads off:
A41: 8 | C41: 610mm diameter bored pile | D41: No | E41: =SUM(I41:N41) -> 0 | F41: 875 | G41: =+E41*F41 -> 0 | I41: =I14 -> 0 | J41: =J14 -> 0 | K41: =K14 -> 0 | L41: =L14 -> 0 | M41: =M14 -> 0 | N41: =N14 -> 0
B43: SANS 1200D | C43: EARTHWORKS
A45: 9 | B45: 8.3.3 | C45: Rip and scarify in-situ material for a depth of 150mm, breaking down oversize material, adding suitable material where necessary and compact to 93% Mod AASHTO density | D45: m2 | E45: =SUM(I45:N45) -> 653 | F45: 225 | G45: =+E45*F45 -> 146925 | I45: 653
A48: CARRIED FORWARD | G48: =SUM(G8:G47) -> 146925
A51: ITEM NO | B51: PAY REF | C51: DESCRIPTION | D51: UNIT | E51: QTY | F51: RATE | G51: AMOUNT
A52: BROUGHT FORWARD | G52: =+G48 -> 146925
B54: 1200D | C54: EARTHWORKS
B56: 8.3.3 | C56: Restricted excavation
C58: Excavation for restricted foundations in all materials and dispose spoil material at a site provided by the Contractor
A60: 10 | C60: Depth up to 2m | D60: m3 | E60: =SUM(I60:N60) -> 150.4 | F60: 175 | G60: =+E60*F60 -> 26320 | J60: 88 | L60: 62.4
C62: Extra overs on Item above for:
A64: 11 | C64: Soilcrete backfill under structures as indicated on the drawings or directed by the Engineer | D64: m3 | E64: =SUM(I64:N64) -> 0 | F64: 950 | G64: =+E64*F64 -> 0
C66: (The aggregate of soilcrete shall be mixed with 5% cement of volume and shall consist of approved soil or gravel containing stones, obtained from commercial sources, not bigger than 38mm and with a plasticity index not exceeding 10)
B68: 8.3.4 | C68: Importing of materials
C70: Extra over item for importation of materials from commercial sources:
A72: 12 | C72: Backfill with G5 material compacted to 93% MOD AASHTO from commercial sources selected by the Contractor | D72: m3 | E72: =SUM(I72:N72) -> 86.1 | F72: 725 | G72: =+E72*F72 -> 62422.5 | J72: 49 | L72: 37.1
...

Sheet Centrifuge Bunded
A1: GEORGE BIOMASS POWER PLANT
A2: =Summary!A2 -> NAFASI WATER - ARNOT WASTE TREATMENT PLANT | G2: =Summary!C2 -> Revision T1
A3: =Summary!A3 -> PILING AND CIVIL WORK
A4: SECTION 13 - BILL OF QUANTITIES | G4: =Summary!C4 -> 45183
A6: ITEM NO | B6: PAY REF | C6: DESCRIPTION | D6: UNIT | E6: QTY | F6: RATE | G6: AMOUNT | I6: Foundations | J6: Surface Beds | K6: Retaining Wall | L6: Sump
C8: CENTRIFUGE BUNDED AREA
B10: SANS 1200F | C10: PILING (BORED PILES) | E10: =IF(SUM(H10:M10)>0,SUM(H10:M10),"")
E11: =IF(SUM(H11:M11)>0,SUM(H11:M11),"")
C12: Move equipment and setup: | E12: =IF(SUM(H12:M12)>0,SUM(H12:M12),"")
E13: =IF(SUM(H13:M13)>0,SUM(H13:M13),"")
A14: 1 | C14: Move equipment to and set up each pile position for heavy bored cast-in-situ piles (610mm diameter) | D14: No | E14: =SUM(I14:N14) -> 0 | F14: 1150 | G14: =+E14*F14 -> 0 | I14: 0 | J14: 0 | K14: 0 | L14: 0
C16: Bore Holes for Piles:
C17: Bored holes for cast-in-situ piles of 610mm diameter (heavy) through material situated in the following successive depth ranges:
A19: 2 | C19: 0m up to 10m | D19: m | E19: =SUM(I19:N19) -> 0 | F19: 1850 | G19: =+E19*F19 -> 0 | I19: =I14*10 -> 0 | J19: =J14*10 -> 0 | K19: =K14*10 -> 0 | L19: =L14*10 -> 0
A21: 3 | C21: 10m up to 20m | D21: m | E21: =SUM(I21:N21) -> 0 | F21: =F19 -> 1850 | G21: =+E21*F21 -> 0 | I21: =I14*5 -> 0 | J21: =J14*5 -> 0 | K21: =K14*5 -> 0 | L21: =L14*5 -> 0
C23: Forming of Bulbous bases:
A25: 4 | C25: For DCS piles of 610mm diameter | D25: No | E25: =SUM(I25:N25) -> 0 | F25: 1250 | G25: =+E25*F25 -> 0 | I25: =I14 -> 0 | J25: =J14 -> 0 | K25: =K14 -> 0 | L25: =L14 -> 0
C27: Steel reinforcement in cast-in-situ piles:
A29: 5 | C29: Mild steel, Plain | D29: t | E29: =SUM(I29:N29) -> 0 | F29: 29500 | G29: =+E29*F29 -> 0 | I29: =(I19+I21)*0.00325 -> 0 | J29: =(J19+J21)*0.00325 -> 0 | K29: =(K19+K21)*0.00325 -> 0 | L29: =(L19+L21)*0.00325 -> 0
A31: 6 | C31: High yield stress steel | D31: t | E31: =SUM(I31:AG31) -> 0 | F31: 28000 | G31: =+E31*F31 -> 0 | I31: =(I19+I21)*0.0215 -> 0 | J31: =(J19+J21)*0.0215 -> 0 | K31: =(K19+K21)*0.0215 -> 0 | L31: =(L19+L21)*0.0215 -> 0
C33: Concrete for cast-in-situ piles, under reams and sockets:
A35: 7 | C35: Compressive Strength 30Mpa/19mm
C37: Piles | D37: m3 | E37: =SUM(I37:N37) -> 0 | F37: 3500 | G37: =+E37*F37 -> 0 | I37: =((I19+I21)*0.292)+(I14*0.75) -> 0 | J37: =((J19+J21)*0.292)+(J14*0.75) -> 0 | K37: =((K19+K21)*0.292)+(K14*0.75) -> 0 | L37: =((L19+L21)*0.292)+(L14*0.75) -> 0
B39: PSF 8.2.20 | C39: Strip / cut heads off:
A41: 8 | C41: 610mm diameter bored pile | D41: No | E41: =SUM(I41:N41) -> 0 | F41: 875 | G41: =+E41*F41 -> 0 | I41: =I14 -> 0 | J41: =J14 -> 0 | K41: =K14 -> 0 | L41: =L14 -> 0
B43: SANS 1200D | C43: EARTHWORKS
A45: 9 | B45: 8.3.3 | C45: Rip and scarify in-situ material for a depth of 150mm, breaking down oversize material, adding suitable material where necessary and compact to 93% Mod AASHTO density | D45: m2 | E45: =SUM(I45:N45) -> 101 | F45: 225 | G45: =+E45*F45 -> 22725 | J45: 101
A48: CARRIED FORWARD | G48: =SUM(G8:G47) -> 22725
A51: ITEM NO | B51: PAY REF | C51: DESCRIPTION | D51: UNIT | E51: QTY | F51: RATE | G51: AMOUNT
A52: BROUGHT FORWARD | G52: =+G48 -> 22725
B54: 1200D | C54: EARTHWORKS
B56: 8.3.3 | C56: Restricted excavation
C58: Excavation for restricted foundations in all materials and dispose spoil material at a site provided by the Contractor
A60: 10 | C60: Depth up to 2m | D60: m3 | E60: =SUM(I60:N60) -> 113.9 | F60: 175 | G60: =+E60*F60 -> 19932.5 | I60: 12.5 | K60: 39 | L60: 62.4
C62: Extra overs on Item above for:
A64: 11 | C64: Soilcrete backfill under structures as indicated on the drawings or directed by the Engineer | D64: m3 | E64: =SUM(I64:N64) -> 0 | F64: 950 | G64: =+E64*F64 -> 0
C66: (The aggregate of soilcrete shall be mixed with 5% cement of volume and shall consist of approved soil or gravel containing stones, obtained from commercial sources, not bigger than 38mm and with a plasticity index not exceeding 10)
B68: 8.3.4 | C68: Importing of materials
C70: Extra over item for importation of materials from commercial sources:
A72: 12 | C72: Backfill with G5 material compacted to 93% MOD AASHTO from commercial sources selected by the Contractor | D72: m3 | E72: =SUM(I72:N72) -> 64.8 | F72: 725 | G72: =+E72*F72 -> 46980 | I72: 5.7 | K72: 22 | L72: 37.1
...

Sheet Stockpile and Crane
A1: GEORGE BIOMASS POWER PLANT
A2: =Summary!A2 -> NAFASI WATER - ARNOT WASTE TREATMENT PLANT | G2: =Summary!C2 -> Revision T1
A3: =Summary!A3 -> PILING AND CIVIL WORK
A4: SECTION 14 - BILL OF QUANTITIES | G4: =Summary!C4 -> 45183
A6: ITEM NO | B6: PAY REF | C6: DESCRIPTION | D6: UNIT | E6: QTY | F6: RATE | G6: AMOUNT | I6: Surface Beds | J6: Retaining Wall
C8: STOCKPILE AND CRANE HARDSTANDS
B10: SANS 1200F | C10: PILING (BORED PILES) | E10: =IF(SUM(H10:M10)>0,SUM(H10:M10),"")
E11: =IF(SUM(H11:M11)>0,SUM(H11:M11),"")
C12: Move equipment and setup: | E12: =IF(SUM(H12:M12)>0,SUM(H12:M12),"")
E13: =IF(SUM(H13:M13)>0,SUM(H13:M13),"")
A14: 1 | C14: Move equipment to and set up each pile position for heavy bored cast-in-situ piles (610mm diameter) | D14: No | E14: =SUM(I14:N14) -> 0 | F14: 1150 | G14: =+E14*F14 -> 0 | I14: 0 | J14: 0
C16: Bore Holes for Piles:
C17: Bored holes for cast-in-situ piles of 610mm diameter (heavy) through material situated in the following successive depth ranges:
A19: 2 | C19: 0m up to 10m | D19: m | E19: =SUM(I19:N19) -> 0 | F19: 1850 | G19: =+E19*F19 -> 0 | I19: =I14*10 -> 0 | J19: =J14*10 -> 0
