Workbook

Sheet S1-P&G'S
A2: NAFASI WATER - ARNOT WATER AND SEWER | G2: Revision T1
A3: EARTHWORKS AND CIVIL WORK
A4: SECTION 1 - BILL OF QUANTITIES | G4: 45184
A6: ITEM NO | B6: PAY REF | C6: DESCRIPTION | D6: UNIT | E6: QTY | F6: Rate (R) | G6: AMOUNT (R)
B8: SANS 1200A | C8: SECTION 1 - PRELIMINARY AND GENERAL
B10: 8.3 | C10: FIXED CHARGE ITEMS
A12: 1 | B12: 8.3.1 | C12: Contractual requirements (excluding insurance and performance bond) | D12: SUM | E12: 1 | G12: =E12*F12 -> 0
B14: 8.3.2 | C14: Establishment of Facilities on the Site
B16: 8.3.2.1 | C16: Facilities for Engineer
B18: 8.3.2.1a | C18: Furnished Boardroom (1 No - Eight persons) | D18: SUM | E18: 1 | G18: =E18*F18 -> 0
B20: 8.3.2.1c | C20: Nameboard (1 No). | D20: SUM | E20: 1 | G20: =E20*F20 -> 0
B22: 8.3.2.2 | C22: Facilities for Contractor
A24: 2 | B24: 8.3.2.2a | C24: Offices and storage sheds. | D24: SUM | E24: 1 | G24: =E24*F24 -> 0
A26: 3 | B26: 8.3.2.2b | C26: Workshops. | D26: SUM | E26: 1 | G26: =E26*F26 -> 0
A28: 4 | B28: 8.3.2.2c | C28: Laboratories. | D28: SUM | E28: 1 | G28: =E28*F28 -> 0
A30: 5 | B30: 8.3.2.2d | C30: Living accommodation. | D30: SUM | E30: 1 | G30: =E30*F30 -> 0
A32: 6 | B32: 8.3.2.2e | C32: Ablution and latrine facilities. | D32: SUM | E32: 1 | G32: =E32*F32 -> 0
A34: 7 | B34: 8.3.2.2f | C34: Tools and equipment. | D34: SUM | E34: 1 | G34: =E34*F34 -> 0
A36: 8 | B36: 8.3.2.2g | C36: Water supplies, electric power and communications | D36: SUM | E36: 1 | G36: =E36*F36 -> 0
A38: 9 | B38: 8.3.2.2h | C38: Dealing with water | D38: SUM | E38: 1 | G38: =E38*F38 -> 0
A40: 10 | B40: 8.3.2.2i | C40: Access | D40: SUM | E40: 1 | G40: =E40*F40 -> 0
A42: 11 | B42: 8.3.2.2j | C42: Plant | D42: SUM | E42: 1 | G42: =E42*F42 -> 0
A44: 12 | B44: 8.3.3 | C44: Other fixed charge obligations. | D44: SUM | E44: 1 | G44: =E44*F44 -> 0
A46: 13 | B46: 8.3.4 | C46: Removal of site establishment. | D46: SUM | E46: 1 | G46: =E46*F46 -> 0
... A50: 15 | B50: PSA 8.3.6 | C50: Performance Bond | D50: SUM | E50: 1 | G50: =E50*F50 -> 0
B52: 8.4 | C52: TIME RELATED ITEMS
A54: 16 | B54: 8.4.1 | C54: Contractual requirements (excluding insurance and performance bond) | D54: SUM | E54: 1 | G54: =E54*F54 -> 0
B56: 8.4.2 | C56: Operation and Maintenance of Facilities on Site, for Duration of Construction, (unless otherwise stated)
A63: CARRIED FORWARD | G63: =SUM(G7:G62) -> 0
A66: ITEM NO | B66: PAY REF | C66: DESCRIPTION | D66: UNIT | E66: QTY | F66: RATE (R) | G66: AMOUNT (R)
A67: BROUGHT FORWARD | G67: =G63 -> 0
B69: 8.4.2.1 | C69: Facilities for Engineer
A71: 17 | B71: 8.4.2.1a | C71: Furnished Boardroom (1 No - Eight persons) | D71: SUM | E71: 1 | G71: =E71*F71 -> 0
A73: 18 | B73: 8.4.2.1c | C73: Nameboard (1 No). | D73: SUM | E73: 1 | G73: =E73*F73 -> 0
A75: 19 | B75: 8.4.2.1d | C75: Survey assistants and material | D75: SUM | E75: 1 | G75: =E75*F75 -> 0
B77: 8.4.2.2 | C77: Facilities for Contractor
A79: 20 | B79: 8.4.2.2a | C79: Offices and storage sheds. | D79: SUM | E79: 1 | G79: =E79*F79 -> 0
A81: 21 | B81: 8.4.2.2b | C81: Workshops. | D81: SUM | E81: 1 | G81: =E81*F81 -> 0
A83: 22 | B83: 8.4.2.2c | C83: Laboratories. | D83: SUM | E83: 1 | G83: =E83*F83 -> 0
A85: 23 | B85: 8.4.2.2d | C85: Living accommodation. | D85: SUM | E85: 1 | G85: =E85*F85 -> 0
...

Sheet S2-ENGINEERED PLATFORM & PAVING
A1: ='S1-P&G''S'!A2 -> NAFASI WATER - ARNOT WATER AND SEWER | G1: ='S1-P&G''S'!G2 -> Revision T1
A2: ='S1-P&G''S'!A3 -> EARTHWORKS AND CIVIL WORK
A3: SECTION 2 - EARTHWORKS & INTERLOCKING PAVING | G3: ='S1-P&G''S'!G4 -> 45184
A5: ITEM NO | B5: PAY REF | C5: DESCRIPTION | D5: UNIT | E5: QTY | F5: Rate (R) | G5: AMOUNT (R)
C7: =A3 -> SECTION 2 - EARTHWORKS & INTERLOCKING PAVING
B9: SANS 1200C | C9: SITE CLEARANCE
B10: 8.2.1 | C10: Clear and grub:
C11: Remove and grub all trees and tree stumps including the removal of all roots that may remain in the soil all vegetation. and stripping of the surface soil to a depth of 150mm. The clearing only needs to follow the natural surface.
A13: 1 | C13: Areas | D13: m2 | E13: 24640 | F13: 10.5 | G13: =E13*F13 -> 258720
B15: 8.2.2 | C15: Remove and grub large trees and tree stumps of girth:
A17: 2 | C17: Over 1,0 m and up to and including 2,0m | D17: No | E17: 5 | F17: 5000 | G17: =E17*F17 -> 25000
B19: SANS
B20: 1200D | C20: EARTHWORKS
B22: 8.3.2 | C22: Bulk excavation:
C24: Excavate in TopSoil materials (350mm thickness) and dispose.
A26: 3 | C26: Excavate in all materials and dispose at spoil site to be identified by Contractor | D26: m3 | E26: 12617 | F26: 115 | G26: =E26*F26 -> 1450955
A28: 4 | C28: Excavate in all materials and fill material in 150 mm layers, compacted to 93% MOD AASHTO to engineers instruction | D28: m3 | E28: 800 | F28: 245 | G28: =E28*F28 -> 196000
B30: SANS
B31: 1200DM | C31: EARTHWORKS (ROADS, SUBGRADE)
B33: 8.3.3 | C33: Treatment of roadbed:
A35: 5 | C35: 150mm Roadbed preparation and compaction of material to minimum of 95% of MOD AASHTO maximum to 150 mm deep | D35: m2 | E35: 24640 | F35: 23 | G35: =E35*F35 -> 566720
B36: SANS
B37: 1200ME | C37: SUBBASE
B38: 8.3.3 | C38: Selected layers compacted to 95% of modified AASHTO maximum density obtained from commercial resources
A40: 6 | C40: G5 Material 150mm thick subbase platform | D40: m3 | E40: 8270 | F40: 725 | G40: =E40*F40 -> 5995750
A42: 7 | C42: G6 Material 150mm thick subbase platform | D42: m3 | E42: 17600 | F42: 625 | G42: =E42*F42 -> 11000000
B44: SANS
B45: 1200ME | C45: SUBBASE
B46: 8.3.3 | C46: Selected layers compacted to 95% of modified AASHTO maximum density obtained from commercial resources
A48: 8 | C48: G5 Material (2x150mm thick + 1x200mm thick) subbase platform | D48: m3 | E48: 1790 | F48: 725 | G48: =E48*F48 -> 1297750
B51: 8.3.5 | C51: Process subbase material by one of the following processes, as relevant, and use in the subbase:
A53: 9 | C53: Stabilization | D53: m3 | E53: 1790 | F53: 89 | G53: =E53*F53 -> 159310
B55: 8.3.8 | C55: Stabilizing agent:
A57: 10 | C57: Portland cement | D57: t | E57: =ROUNDUP(E53*(3/100)*1.61,0) -> 87 | F57: 2596 | G57: =E57*F57 -> 225852
A62: CARRIED FORWARD | G62: =SUM(G6:G57) -> 21176057
A65: ITEM NO | B65: PAY REF | C65: DESCRIPTION | D65: UNIT | E65: QTY | F65: RATE (USD) | G65: AMOUNT (USD)
A66: BROUGHT FORWARD | G66: =G62 -> 21176057
B68: SANS
B69: 1200MJ | C69: SEGMENTED PAVING
B70: 8.2.2 | C70: Construction of paving complete
...

Sheet S3-STORMWATER
A1: ='S1-P&G''S'!A2 -> NAFASI WATER - ARNOT WATER AND SEWER | G1: ='S1-P&G''S'!G2 -> Revision T1
A2: ='S1-P&G''S'!A3 -> EARTHWORKS AND CIVIL WORK
A3: SECTION 3 - STORM WATER DRAINAGE | G3: ='S1-P&G''S'!G4 -> 45184
A5: ITEM NO | B5: PAY REF | C5: DESCRIPTION | D5: UNIT | E5: QTY | F5: Rate (R) | G5: AMOUNT (R)
C7: =A3 -> SECTION 3 - STORM WATER DRAINAGE
B8: SANS
B9: 1200D | C9: EARTHWORKS
B11: 8.3.3 | C11: Restricted excavation
C13: Excavation for restricted foundations in all materials and dispose spoil material at a site provided by the Contractor
A15: 1 | C15: Depth up to 1m | D15: m3 | E15: 100 | F15: 450 | G15: =E15*F15 -> 45000
B17: SANS 1200DB | C17: EARTHWORKS (PIPE TRENCHES)
B19: 8.3.2 | C19: Excavate in all materials for trenches, backfill and compact and dispose of surplus material:
C21: Pipes over 250mm diameter up to 500mm diameter for depths:
A23: 2 | C23: Over 1,0m up to 2,0m | D23: m | E23: 70 | F23: 178 | G23: =E23*F23 -> 12460
B25: SANS
B26: 1200G | C26: CONCRETE (STRUCTURAL)
B28: 8.2 | C28: SCHEDULED FORMWORK ITEMS
B30: 8.2.1 | C30: Rough:
C31: (No treatment of the surface of the concrete will be required after striking of the formwork)
C33: Vertical formwork to:
B35: 8.2.5 | C35: Narrow Widths (up to 300mm wide):
A37: 3 | C37: Over 100mm and up to 200mm (rough) | D37: m | E37: 1600 | F37: 135 | G37: =E37*F37 -> 216000
B39: 8.3 | C39: SCHEDULED REINFORCING ITEMS
B41: 8.3.2 | C41: High Tensile Welded Mesh
C42: (The unit rate for welded mesh shall cover the supply, cutting and placing of the mesh and the cost of all waste due to overlaps)
A44: 4 | C44: Ref.395 mesh reinforcement | D44: m2 | E44: 1600 | F44: 345 | G44: =E44*F44 -> 552000
B46: 8.4 | C46: SCHEDULED CONCRETE ITEMS
B48: 8.4.3 | C48: Strength concrete:
C50: Class 25MPa/19mm in:
A52: 5 | C52: Canal | D52: m3 | E52: 108 | F52: 3250 | G52: =E52*F52 -> 351000
A59: CARRIED FORWARD | G59: =SUM(G6:G58) -> 1176460
A62: ITEM NO | B62: PAY REF | C62: DESCRIPTION | D62: UNIT | E62: QTY | F62: RATE (R) | G62: AMOUNT (R)
A63: BROUGHT FORWARD | G63: =G59 -> 1176460
B65: 8.4.4 | C65: Unformed Surface Finishes
C67: Wood-floated finish to:
A69: 6 | C69: Canal | D69: m2 | E69: 1550 | F69: 46 | G69: =E69*F69 -> 71300
B71: 8.5 | C71: JOINTS
C73: Canal Expansion Joints
A75: 7 | C75: 150mm high Bitumen Impregnated Fibreboard with 10mm x 10mm Sika Joint Sealer (3m c/c) | D75: m2 | E75: 74 | F75: 750 | G75: =E75*F75 -> 55500
B77: SANS 1200LB | C77: BEDDING FOR PIPES
...

Sheet S4-SEWER
A1: ='S1-P&G''S'!A2 -> NAFASI WATER - ARNOT WATER AND SEWER | G1: ='S1-P&G''S'!G2 -> Revision T1
A2: ='S1-P&G''S'!A3 -> EARTHWORKS AND CIVIL WORK
A3: SECTION 4 - SEWER | G3: ='S1-P&G''S'!G4 -> 45184
A5: ITEM NO | B5: PAY REF | C5: DESCRIPTION | D5: UNIT | E5: QTY | F5: Rate (R) | G5: AMOUNT (R)
C7: =A3 -> SECTION 4 - SEWER
B8: SANS
B9: 1200DB | C9: EARTHWORKS (PIPE TRENCHES)
B11: 8.3.2 | C11: Excavate in all materials for trenches, backfill and compact and dispose of surplus material:
C13: Pipes up to 250mm diameter for depths:
A15: 1 | C15: Over 1,0m up to 2,5m | D15: m | E15: 140 | F15: 290 | G15: =E15*F15 -> 40600
B17: SANS
B18: 1200LB | C18: BEDDING FOR PIPES
B20: 8.2.2.3 | C20: Provision of bedding from commercial sources:
A22: 2 | C22: Selected granular material | D22: m3 | E22: 17 | F22: 519 | G22: =E22*F22 -> 8823
A24: 3 | C24: Selected fill material | D24: m3 | E24: 38 | F24: 519 | G24: =E24*F24 -> 19722
A26: 4 | C26: Soilcrete backfill above pipes as indicated on the drawings or directed by the Engineer | D26: m3 | E26: 5 | F26: 950 | G26: =E26*F26 -> 4750
B28: SANS
B29: 1200LD | C29: SEWER RETICULATION
B31: 8.2.1 | C31: Supply, lay, test and bed on class B bedding and test pipeline for the following diameters:
A33: 5 | C33: 160mm diameter CL 400 (uPVC) | D33: m | E33: 140 | F33: 638 | G33: =E33*F33 -> 89320
B35: 8.2.3 | C35: Supply and construct precast manholes complete for pipes up to 200mm diameter including base, rings cover slab and heavy duty cover and frame for the following depths:
A37: 6 | C37: Depth up to 1m | D37: No | E37: 3 | F37: 16875 | G37: =E37*F37 -> 50625
A39: 7 | C39: Depth up to 2m | D39: No | E39: 1 | F39: 18862 | G39: =E39*F39 -> 18862
B41: 8.2.5 | C41: Cleaning Eyes
A43: 8 | C43: 160mm diameter CL 400 (uPVC) | D43: No | E43: 3 | F43: 210 | G43: =E43*F43 -> 630
A45: 9 | C45: Sewer Water Holding Tanke | D45: No | E45: 1 | F45: 36000 | G45: =E45*F45 -> 36000
C47: Miscellaneous work
A49: 10 | C49: Oil Separators and Soakaway | D49: PC Sum | E49: 1 | F49: 75000 | G49: =F49*E49 -> 75000
A51: 11 | C51: Charge required by Contractor on item 12 above | D51: % | E51: 1 | F51: 5000 | G51: =E51*F51 -> 5000
A60: TOTAL AMOUNT FOR SECTION CARRIED TO SUMMARY | G60: =SUM(G6:G59) -> 349332

Sheet S5-WATER
A1: ='S1-P&G''S'!A2 -> NAFASI WATER - ARNOT WATER AND SEWER | G1: ='S1-P&G''S'!G2 -> Revision T1
A2: ='S1-P&G''S'!A3 -> EARTHWORKS AND CIVIL WORK
A3: SECTION 5 - WATER RETICULATION | G3: ='S1-P&G''S'!G4 -> 45184
A5: ITEM NO | B5: PAY REF | C5: DESCRIPTION | D5: UNIT | E5: QTY | F5: Rate (R) | G5: AMOUNT (R)
C7: =A3 -> SECTION 5 - WATER RETICULATION
B8: SANS
B9: 1200DB | C9: EARTHWORKS (PIPE TRENCHES)
B11: 8.3.2 | C11: Excavate in all materials for trenches, backfill and compact and dispose of surplus material:
C13: Pipes up to 250mm diameter for depths:
A15: 1 | C15: Over 1,0m up to 2,0m | D15: m | E15: 305 | F15: 235 | G15: =E15*F15 -> 71675
B17: SANS
B18: 1200L | C18: MEDIUM-PRESSURE PIPE LINES
B20: 8.2.1 | C20: Supply, lay, test and bed on class B bedding complete with couplings for the following diameters:
C22: HDPE class 16 pipes:
A24: 4 | C24: 63mm diameter PN 12 | D24: m | E24: 305 | F24: 750 | G24: =E24*F24 -> 228750
B26: 8.2.2 | C26: Extra over on item 2 for the supplying, laying and bedding of uPVC specials complete with couplings:
C28: 90° bends:
A30: 5 | C30: 25 to 75mm diameter PN 12 | D30: No | E30: 14 | F30: 580 | G30: =E30*F30 -> 8120
C32: Tees:
A34: 6 | C34: 25 to 75mm diameter PN 12 | D34: No | E34: 6 | F34: 580 | G34: =E34*F34 -> 3480
B36: 8.2.3 | C36: Extra over on item 2 for supplying, fixing, testing and bedding RSV gate valves for the following diameters:
A38: 7 | C38: 63mm diameter PN 12 | D38: No | E38: 6 | F38: 3800 | G38: =E38*F38 -> 22800
B40: 8.2.11 | C40: Anchor/thrust blocks and pedestals:
A42: 8 | C42: Concrete - Class 25 Mpa/19mm | D42: m3 | E42: 4 | F42: 3250 | G42: =E42*F42 -> 13000
A44: 9 | C44: Reinforcement (High Tensile) | D44: t | E44: 0.4 | F44: 25750 | G44: =E44*F44 -> 10300
B46: 8.2.12 | C46: Concrete casing:
A48: 10 | C48: Class 25 Mpa/19mm | D48: m3 | E48: 1 | F48: 3250 | G48: =E48*F48 -> 3250
A61: CARRIED FORWARD | G61: =SUM(G6:G60) -> 361375
A64: ITEM NO | B64: PAY REF | C64: DESCRIPTION | D64: UNIT | E64: QTY | F64: RATE (R) | G64: AMOUNT (R)
A65: BROUGHT FORWARD | G65: =G61 -> 361375
B67: SANS
B68: 1200LB | C68: BEDDING FOR PIPES
B70: 8.2.2.3 | C70: Provision of bedding from commercial sources:
A72: 11 | C72: Selected granular material | D72: m3 | E72: 26 | F72: 519 | G72: =E72*F72 -> 13494
A74: 12 | C74: Selected fill material | D74: m3 | E74: 66 | F74: 519 | G74: =E74*F74 -> 34254
A76: 13 | C76: Soilcrete backfill above pipes as indicated on the drawings or directed by the Engineer | D76: m3 | E76: 5 | F76: 950 | G76: =E76*F76 -> 4750
C78: MISCELLANEOUS WORK
B80: 8.2.13 | C80: Valve chambers etc.:
A82: 14 | C82: Valve chamber | D82: No | E82: 2 | F82: 350 | G82: =E82*F82 -> 700
A83: 15 | B83: PSL 8.2.18 | C83: Connection to existing to main supply pipe | D83: No | E83: 1 | F83: 5000 | G83: =E83*F83 -> 5000
...

Sheet S6-SUMMARY
A1: ='S1-P&G''S'!A2 -> NAFASI WATER - ARNOT WATER AND SEWER | C1: ='S1-P&G''S'!G2 -> Revision T1
A2: ='S1-P&G''S'!A3 -> EARTHWORKS AND CIVIL WORK
A3: SUMMARY | C3: ='S1-P&G''S'!G4 -> 45184
A5: SECTION | B5: DESCRIPTION | C5: AMOUNT (R)
A7: 1 | B7: ='S1-P&G''S'!C8 -> SECTION 1 - PRELIMINARY AND GENERAL | C7: ='S1-P&G''S'!G120 -> 7653637.8
A9: 2 | B9: ='S2-ENGINEERED PLATFORM & PAVING'!C7 -> SECTION 2 - EARTHWORKS & INTERLOCKING PAVING | C9: =+'S2-ENGINEERED PLATFORM & PAVING'!G126 -> 28122182
A11: 3 | B11: ='S3-STORMWATER'!C7 -> SECTION 3 - STORM WATER DRAINAGE | C11: =+'S3-STORMWATER'!G118 -> 1503464
A13: 4 | B13: ='S4-SEWER'!C7 -> SECTION 4 - SEWER | C13: =+'S4-SEWER'!G60 -> 349332
A15: 5 | B15: ='S5-WATER'!C7 -> SECTION 5 - WATER RETICULATION | C15: =+'S5-WATER'!G110 -> 419573
A49: TOTAL AMOUNT CARRIED TO LETTER OF TENDER (VAT EXCLUDED) | C49: =SUM(C7:C48) -> 38048189
