Workbook

Sheet Section 1 - P&G
A1: NAFASI WATER - ARNOT WASTE TREATMENT PLANT | G1: Revision T1
A2: STRUCTURAL STEELWORK SCHEDULE OF QUANTITIES
A3: SECTION 1 : PRELIMINARY AND GENERAL | G3: 45183
A5: PAYMENT REFERS TO | B5: ITEM NO | C5: DESCRIPTION | D5: UNIT | E5: QTY | F5: RATE | G5: AMOUNT
A7: SANS | C7: =A3 -> SECTION 1 : PRELIMINARY AND GENERAL
A8: 1200A | C8: (Applicable to the whole of the Works)
A10: 8.3 | C10: FIXED CHARGE ITEMS
A12: 8.3.1 | B12: 1 | C12: Contractual requirements (excluding insurance and | D12: SUM | E12: 1 | G12: =E12*F12 -> 0
C13: performance bond)
A15: 8.3.2 | C15: Establishment of Facilities on the Site
A17: 8.3.2.1 | C17: Facilities for Engineer
A19: 8.3.2.1a | B19: 2 | C19: Furnished Office (1 No) | D19: SUM | E19: 1 | G19: =E19*F19 -> 0
A21: 8.3.2.1c | B21: 3 | C21: Nameboard (1 No). | D21: SUM | E21: 1 | G21: =E21*F21 -> 0
A23: 8.3.2.2 | C23: Facilities for Contractor
A25: 8.3.2.2a | B25: 4 | C25: Offices and storage sheds. | D25: SUM | E25: 1 | G25: =E25*F25 -> 0
A27: 8.3.2.2b | B27: 5 | C27: Workshops. | D27: SUM | E27: 1 | G27: =E27*F27 -> 0
A29: 8.3.2.2c | B29: 6 | C29: Laboratories. | D29: SUM | E29: 1 | G29: =E29*F29 -> 0
A31: 8.3.2.2d | B31: 7 | C31: Living accommodation. | D31: SUM | E31: 1 | G31: =E31*F31 -> 0
A33: 8.3.2.2f | B33: 8 | C33: Tools and equipment. | D33: SUM | E33: 1 | G33: =E33*F33 -> 0
A35: 8.3.2.2g | B35: 9 | C35: Water supplies, electric power and communications | D35: SUM | E35: 1 | G35: =E35*F35 -> 0
A37: 8.3.2.2h | B37: 10 | C37: Dealing with water | D37: SUM | E37: 1 | G37: =E37*F37 -> 0
A39: 8.3.2.2i | B39: 11 | C39: Access | D39: SUM | E39: 1 | G39: =E39*F39 -> 0
A41: 8.3.2.2j | B41: 12 | C41: Plant (Free issue: Front end loader, operator and diesel) | D41: SUM | E41: 1 | G41: =E41*F41 -> 0
A43: 8.3.3 | B43: 13 | C43: Other fixed charge obligations. | D43: SUM | E43: 1 | G43: =E43*F43 -> 0
A45: 8.3.4 | B45: 14 | C45: Removal of site establishment. | D45: SUM | E45: 1 | G45: =E45*F45 -> 0
A47: PSA 8.3.5 | B47: 15 | C47: Insurance | D47: SUM | E47: 1 | G47: =E47*F47 -> 0
A49: PSA 8.3.6 | B49: 16 | C49: Performance Bond | D49: SUM | E49: 1 | G49: =E49*F49 -> 0
A60: SECTION 1 - CARRIED FORWARD | G60: =SUM(G6:G59) -> 0
A63: PAYMENT REFERS TO | B63: ITEM NO | C63: DESCRIPTION | D63: UNIT | E63: QTY | F63: RATE | G63: AMOUNT
A64: SECTION 1 - BROUGHT FORWARD | G64: =G60 -> 0
A66: 8.4 | C66: TIME RELATED ITEMS
A68: 8.4.1 | B68: 17 | C68: Contractual requirements (excluding insurance and | D68: SUM | E68: 1 | G68: =E68*F68 -> 0
C69: performance bond).
A71: 8.4.2 | B71: 18 | C71: Operation and Maintenance of Facilities on Site, for | D71: SUM | E71: 1 | G71: =E71*F71 -> 0
C72: Duration of Construction, (unless otherwise stated).
A74: 8.4.2.1 | C74: Facilities for Engineer
A76: 8.4.2.1a | B76: 19 | C76: Furnished Office (1 No). | D76: SUM | E76: 1 | G76: =E76*F76 -> 0
A78: 8.4.2.1c | B78: 20 | C78: Nameboard (1 No). | D78: SUM | E78: 1 | G78: =E78*F78 -> 0
A80: 8.4.2.1d | B80: 21 | C80: Survey assistants and material. | D80: SUM | E80: 1 | G80: =E80*F80 -> 0
A82: 8.4.2.2 | C82: Facilities for Contractor
...

Sheet Section 2 - RO Building
A1: ='Section 1 - P&G'!A1 -> NAFASI WATER - ARNOT WASTE TREATMENT PLANT | G1: ='Section 1 - P&G'!G1 -> Revision T1
A2: ='Section 1 - P&G'!A2 -> STRUCTURAL STEELWORK SCHEDULE OF QUANTITIES
A3: SECTION 2: RO BUILDING | G3: ='Section 1 - P&G'!G3 -> 45183
A5: PAYMENT REFERS TO | B5: ITEM NO | C5: DESCRIPTION | D5: UNIT | E5: QUANTITY | F5: RATE | G5: AMOUNT
C7: =A3 -> SECTION 2: RO BUILDING
A9: SANS | C9: STRUCTURAL STEELWORK
A10: 1200H
A11: 8.3.1 | C11: Supply and fabrication:
A13: 8.3.1.1 | B13: 1 | C13: Preparation of shop detail drawings | D13: t | E13: =SUM(E20:E34) -> 50.861 | F13: 1050 | G13: =F13*E13 -> 53404.05
A15: 8.3.1.2 | C15: Supply and fabrication of steelwork, Grade S355JR:
C16: Joint by welding in shop and bolting on site:
C18: Hot-Rolled Steel Sections
B20: 2 | C20: I-section columns | D20: t | E20: 10.967 | F20: 43560 | G20: =F20*E20 -> 477722.52
B22: 3 | C22: I-section gable columns | D22: t | E22: 0.95 | F22: 43560 | G22: =F22*E22 -> 41382
B24: 4 | C24: I-section beams | D24: t | E24: 16.942 | F24: 43560 | G24: =F24*E24 -> 737993.52
B26: 5 | C26: Angle section bracing and sag bars | D26: t | E26: 6.692 | F26: 40920 | G26: =F26*E26 -> 273836.64
B28: 6 | C28: PFC Chanels | D28: t | E28: 3.21 | F28: 43560 | G28: =F28*E28 -> 139827.6
C30: Cold Form Sections (Purlins, Girts, etc.)
B32: 7 | C32: Lipped channel purlins | D32: t | E32: 5.61 | F32: 36800 | G32: =F32*E32 -> 206448
B34: 8 | C34: Lipped channel girts | D34: t | E34: 6.49 | F34: 36800 | G34: =F34*E34 -> 238832
A36: 8.3.2 | C36: Delivery to site
A38: 8.3.2.1 | B38: 9 | C38: Normal delivery | D38: t | E38: =E20+E22+E24+E26+E32+E34+E28 -> 50.861 | F38: 1250 | G38: =F38*E38 -> 63576.25
A40: 8.3.3 | C40: Erection on site
B42: 10 | C42: Structural steelwork and erection bolts | D42: t | E42: =E46+E38 -> 53.149745 | F42: 14250 | G42: =F42*E42 -> 757383.87
A44: 8.3.4 | C44: Erection bolts
A46: 8.3.4.1 | B46: 11 | C46: Grade 8.8 precision galvanised bolts, nuts and washers | D46: t | E46: =E38*0.045 -> 2.288745 | F46: 75750 | G46: =F46*E46 -> 173372.43
A48: 1200HC | C48: CORROSION PROTECTION OF STRUCTURAL STEELWORK
A50: 8.2.1 | B50: 12 | C50: Corrosion protection for all structural steel members must be Hot-Dipped Galvanising applied according to SANS 121 (ISO 1461) | D50: t | E50: =E20+E22+E24+E26+E28+E32+E34 -> 50.861 | F50: 15100 | G50: =F50*E50 -> 768001.1
A53: SECTION 2 - CARRIED FORWARD | G53: =SUM(G6:G52) -> 3931780
A56: PAYMENT REFERS TO | B56: ITEM NO | C56: DESCRIPTION | D56: UNIT | E56: QUANTITY | F56: RATE | G56: AMOUNT
A57: SECTION 2 - BROUGHT FORWARD | G57: =G53 -> 3931780
A59: 1200HB | C59: CLADDING AND SHEETING
A61: 8.2.2 | C61: Supply and install cladding and sheeting:
C63: Roof Cladding:
B65: 13 | C65: 0,8mm IBR 686 prepainted inverted boxed rib sheeting with one stiffener rib in each pan, and with "Colorplus Ultimate Grey" finish of AZ200 on one side in single lengths, fixed to steel purlins with stainless steel top speed screws with galvanised EPDM bonded washers in strict accordance with the manufacturer's specifications. | D65: m2 | E65: 1590 | F65: 550 | G65: =F65*E65 -> 874500
B67: 14 | C67: Extra over roof covering for 82 degrees bullnose to 450mm radius at eaves edge | D67: m | E67: 200 | F67: 350 | G67: =F67*E67 -> 70000
C69: Side Cladding:
B71: 15 | C71: 0,6mm IBR 686 prepainted inverted boxed rib sheeting with one stiffener rib in each pan, and with "Colorplus Ultimate Grey" finish of AZ200 on one side in single lengths, fixed to steel purlins with stainless steel top speed screws with galvanised EPDM bonded washers in strict accordance with the manufacturer's specifications. | D71: m2 | E71: 1465 | F71: 495 | G71: =F71*E71 -> 725175
A73: 8.3.2 | C73: Supply and install ancillaries:
B75: 16 | C75: 0,8mm IBR 686 Ridge cap flashing (600mm girth) with "Colorplus Ultimate Grey" finish of AZ200 complete with serrated closers and poly ridge closers | D75: m | E75: 100 | F75: 550 | G75: =F75*E75 -> 55000
...

Sheet Section 3 - Chemical Store
A1: ='Section 1 - P&G'!A1 -> NAFASI WATER - ARNOT WASTE TREATMENT PLANT | G1: ='Section 1 - P&G'!G1 -> Revision T1
A2: ='Section 1 - P&G'!A2 -> STRUCTURAL STEELWORK SCHEDULE OF QUANTITIES
A3: SECTION 3: CHEMICAL STORE | G3: ='Section 1 - P&G'!G3 -> 45183
A5: PAYMENT REFERS TO | B5: ITEM NO | C5: DESCRIPTION | D5: UNIT | E5: QUANTITY | F5: RATE | G5: AMOUNT
C7: =A3 -> SECTION 3: CHEMICAL STORE
A9: SANS | C9: STRUCTURAL STEELWORK
A10: 1200H
A11: 8.3.1 | C11: Supply and fabrication:
A13: 8.3.1.1 | B13: 1 | C13: Preparation of shop detail drawings | D13: t | E13: =SUM(E20:E34) -> 10.298 | F13: 1050 | G13: =F13*E13 -> 10812.9
A15: 8.3.1.2 | C15: Supply and fabrication of steelwork, Grade S355JR:
C16: Joint by welding in shop and bolting on site:
C18: Hot-Rolled Steel Sections
B20: 2 | C20: I-section columns | D20: t | E20: 2.29 | F20: 43560 | G20: =F20*E20 -> 99752.4
B22: 3 | C22: I-section gable columns | D22: t | E22: 0.49 | F22: 43560 | G22: =F22*E22 -> 21344.4
B24: 4 | C24: I-section beams | D24: t | E24: 2.17 | F24: 43560 | G24: =F24*E24 -> 94525.2
B26: 5 | C26: Angle section bracing and sag bars | D26: t | E26: 1.85 | F26: 40920 | G26: =F26*E26 -> 75702
B28: 6 | C28: PFC Chanels | D28: t | E28: 1.28 | F28: 43560 | G28: =F28*E28 -> 55756.8
C30: Cold Form Sections (Purlins, Girts, etc.)
B32: 7 | C32: Lipped channel purlins | D32: t | E32: 0.718 | F32: 36800 | G32: =F32*E32 -> 26422.4
B34: 8 | C34: Lipped channel girts | D34: t | E34: 1.5 | F34: 36800 | G34: =F34*E34 -> 55200
A36: 8.3.2 | C36: Delivery to site
A38: 8.3.2.1 | B38: 9 | C38: Normal delivery | D38: t | E38: =E20+E22+E24+E26+E32+E34+E28 -> 10.298 | F38: 1250 | G38: =F38*E38 -> 12872.5
A40: 8.3.3 | C40: Erection on site
B42: 10 | C42: Structural steelwork and erection bolts | D42: t | E42: =E46+E38 -> 10.76141 | F42: 14250 | G42: =F42*E42 -> 153350.09
A44: 8.3.4 | C44: Erection bolts
A46: 8.3.4.1 | B46: 11 | C46: Grade 8.8 precision galvanised bolts, nuts and washers | D46: t | E46: =E38*0.045 -> 0.46341 | F46: 75750 | G46: =F46*E46 -> 35103.308
A48: 1200HC | C48: CORROSION PROTECTION OF STRUCTURAL STEELWORK
A50: 8.2.1 | B50: 12 | C50: Corrosion protection for all structural steel members must be Hot-Dipped Galvanising applied according to SANS 121 (ISO 1461) | D50: t | E50: =E20+E22+E24+E26+E28+E32+E34 -> 10.298 | F50: 15100 | G50: =F50*E50 -> 155499.8
A53: SECTION 2 - CARRIED FORWARD | G53: =SUM(G6:G52) -> 796341.8
A56: PAYMENT REFERS TO | B56: ITEM NO | C56: DESCRIPTION | D56: UNIT | E56: QUANTITY | F56: RATE | G56: AMOUNT
A57: SECTION 2 - BROUGHT FORWARD | G57: =G53 -> 796341.8
A59: 1200HB | C59: CLADDING AND SHEETING
A61: 8.2.2 | C61: Supply and install cladding and sheeting:
C63: Roof Cladding:
B65: 13 | C65: 0,8mm IBR 686 prepainted inverted boxed rib sheeting with one stiffener rib in each pan, and with "Colorplus Ultimate Grey" finish of AZ200 on one side in single lengths, fixed to steel purlins with stainless steel top speed screws with galvanised EPDM bonded washers in strict accordance with the manufacturer's specifications. | D65: m2 | E65: 175 | F65: 550 | G65: =F65*E65 -> 96250
B67: 14 | C67: Extra over roof covering for 82 degrees bullnose to 450mm radius at eaves edge | D67: m | E67: 32 | F67: 350 | G67: =F67*E67 -> 11200
C69: Side Cladding:
B71: 15 | C71: 0,6mm IBR 686 prepainted inverted boxed rib sheeting with one stiffener rib in each pan, and with "Colorplus Ultimate Grey" finish of AZ200 on one side in single lengths, fixed to steel purlins with stainless steel top speed screws with galvanised EPDM bonded washers in strict accordance with the manufacturer's specifications. | D71: m2 | E71: 344 | F71: 495 | G71: =F71*E71 -> 170280
A73: 8.3.2 | C73: Supply and install ancillaries:
B75: 16 | C75: 0,8mm IBR 686 Ridge cap flashing (600mm girth) with "Colorplus Ultimate Grey" finish of AZ200 complete with serrated closers and poly ridge closers | D75: m | E75: 16 | F75: 550 | G75: =F75*E75 -> 8800
...

Sheet Section 4 - Workshop
A1: ='Section 1 - P&G'!A1 -> NAFASI WATER - ARNOT WASTE TREATMENT PLANT | G1: ='Section 1 - P&G'!G1 -> Revision T1
A2: ='Section 1 - P&G'!A2 -> STRUCTURAL STEELWORK SCHEDULE OF QUANTITIES
A3: SECTION 4: WORKSHOP | G3: ='Section 1 - P&G'!G3 -> 45183
A5: PAYMENT REFERS TO | B5: ITEM NO | C5: DESCRIPTION | D5: UNIT | E5: QUANTITY | F5: RATE | G5: AMOUNT
C7: =A3 -> SECTION 4: WORKSHOP
A9: SANS | C9: STRUCTURAL STEELWORK
A10: 1200H
A11: 8.3.1 | C11: Supply and fabrication:
A13: 8.3.1.1 | B13: 1 | C13: Preparation of shop detail drawings | D13: t | E13: =SUM(E20:E34) -> 12.11 | F13: 1050 | G13: =F13*E13 -> 12715.5
A15: 8.3.1.2 | C15: Supply and fabrication of steelwork, Grade S355JR:
C16: Joint by welding in shop and bolting on site:
C18: Hot-Rolled Steel Sections
B20: 2 | C20: I-section columns | D20: t | E20: 2.86 | F20: 43560 | G20: =F20*E20 -> 124581.6
B22: 3 | C22: I-section gable columns | D22: t | E22: 0.49 | F22: 43560 | G22: =F22*E22 -> 21344.4
B24: 4 | C24: I-section beams | D24: t | E24: 2.72 | F24: 43560 | G24: =F24*E24 -> 118483.2
B26: 5 | C26: Angle section bracing and sag bars | D26: t | E26: 2.035 | F26: 40920 | G26: =F26*E26 -> 83272.2
B28: 6 | C28: PFC Chanels | D28: t | E28: 1.28 | F28: 43560 | G28: =F28*E28 -> 55756.8
C30: Cold Form Sections (Purlins, Girts, etc.)
B32: 7 | C32: Lipped channel purlins | D32: t | E32: 0.945 | F32: 36800 | G32: =F32*E32 -> 34776
B34: 8 | C34: Lipped channel girts | D34: t | E34: 1.78 | F34: 36800 | G34: =F34*E34 -> 65504
A36: 8.3.2 | C36: Delivery to site
A38: 8.3.2.1 | B38: 9 | C38: Normal delivery | D38: t | E38: =E20+E22+E24+E26+E32+E34+E28 -> 12.11 | F38: 1250 | G38: =F38*E38 -> 15137.5
A40: 8.3.3 | C40: Erection on site
B42: 10 | C42: Structural steelwork and erection bolts | D42: t | E42: =E46+E38 -> 12.65495 | F42: 14250 | G42: =F42*E42 -> 180333.04
A44: 8.3.4 | C44: Erection bolts
A46: 8.3.4.1 | B46: 11 | C46: Grade 8.8 precision galvanised bolts, nuts and washers | D46: t | E46: =E38*0.045 -> 0.54495 | F46: 75750 | G46: =F46*E46 -> 41279.962
A48: 1200HC | C48: CORROSION PROTECTION OF STRUCTURAL STEELWORK
A50: 8.2.1 | B50: 12 | C50: Corrosion protection for all structural steel members must be Hot-Dipped Galvanising applied according to SANS 121 (ISO 1461) | D50: t | E50: =E20+E22+E24+E26+E28+E32+E34 -> 12.11 | F50: 15100 | G50: =F50*E50 -> 182861
A53: SECTION 2 - CARRIED FORWARD | G53: =SUM(G6:G52) -> 936045.2
A56: PAYMENT REFERS TO | B56: ITEM NO | C56: DESCRIPTION | D56: UNIT | E56: QUANTITY | F56: RATE | G56: AMOUNT
A57: SECTION 2 - BROUGHT FORWARD | G57: =G53 -> 936045.2
A59: 1200HB | C59: CLADDING AND SHEETING
A61: 8.2.2 | C61: Supply and install cladding and sheeting:
C63: Roof Cladding:
B65: 13 | C65: 0,8mm IBR 686 prepainted inverted boxed rib sheeting with one stiffener rib in each pan, and with "Colorplus Ultimate Grey" finish of AZ200 on one side in single lengths, fixed to steel purlins with stainless steel top speed screws with galvanised EPDM bonded washers in strict accordance with the manufacturer's specifications. | D65: m2 | E65: 230 | F65: 550 | G65: =F65*E65 -> 126500
B67: 14 | C67: Extra over roof covering for 82 degrees bullnose to 450mm radius at eaves edge | D67: m | E67: 42 | F67: 350 | G67: =F67*E67 -> 14700
C69: Side Cladding:
B71: 15 | C71: 0,6mm IBR 686 prepainted inverted boxed rib sheeting with one stiffener rib in each pan, and with "Colorplus Ultimate Grey" finish of AZ200 on one side in single lengths, fixed to steel purlins with stainless steel top speed screws with galvanised EPDM bonded washers in strict accordance with the manufacturer's specifications. | D71: m2 | E71: 409 | F71: 495 | G71: =F71*E71 -> 202455
A73: 8.3.2 | C73: Supply and install ancillaries:
B75: 16 | C75: 0,8mm IBR 686 Ridge cap flashing (600mm girth) with "Colorplus Ultimate Grey" finish of AZ200 complete with serrated closers and poly ridge closers | D75: m | E75: 22 | F75: 550 | G75: =F75*E75 -> 12100
...

Sheet Section 5 - Piperacks and Stair
A1: ='Section 1 - P&G'!A1 -> NAFASI WATER - ARNOT WASTE TREATMENT PLANT | G1: ='Section 1 - P&G'!G1 -> Revision T1
A2: ='Section 1 - P&G'!A2 -> STRUCTURAL STEELWORK SCHEDULE OF QUANTITIES
A3: SECTION 5: PIPERACKS AND STAICASES | G3: ='Section 1 - P&G'!G3 -> 45183
A5: PAYMENT REFERS TO | B5: ITEM NO | C5: DESCRIPTION | D5: UNIT | E5: QUANTITY | F5: RATE | G5: AMOUNT
C7: =A3 -> SECTION 5: PIPERACKS AND STAICASES
A9: SANS | C9: STRUCTURAL STEELWORK
A10: 1200H
A11: 8.3.1 | C11: Supply and fabrication:
A13: 8.3.1.1 | B13: 1 | C13: Preparation of shop detail drawings | D13: t | E13: =SUM(E20:E28) -> 121.305 | F13: 1050 | G13: =F13*E13 -> 127370.25
A15: 8.3.1.2 | C15: Supply and fabrication of steelwork, Grade S355JR:
C16: Joint by welding in shop and bolting on site:
C18: Hot-Rolled Steel Sections
B20: 2 | C20: I-section columns | D20: t | E20: 38.507 | F20: 43560 | G20: =F20*E20 -> 1677364.9
B22: 3 | C22: I-section beams | D22: t | E22: 65 | F22: 43560 | G22: =F22*E22 -> 2831400
B24: 4 | C24: Angle section bracing and sag bars | D24: t | E24: 11.278 | F24: 40920 | G24: =F24*E24 -> 461495.76
C26: Cold Form Sections (Purlins, Girts, etc.)
B28: 5 | C28: Lipped channel | D28: t | E28: 6.52 | F28: 36800 | G28: =F28*E28 -> 239936
A30: 8.3.2 | C30: Delivery to site
A32: 8.3.2.1 | B32: 6 | C32: Normal delivery | D32: t | E32: =E20+E22+E24+E28 -> 121.305 | F32: 1250 | G32: =F32*E32 -> 151631.25
A34: 8.3.3 | C34: Erection on site
B36: 7 | C36: Structural steelwork and erection bolts | D36: t | E36: =E40+E32 -> 126.76373 | F36: 14250 | G36: =F36*E36 -> 1806383.1
A38: 8.3.4 | C38: Erection bolts
A40: 8.3.4.1 | B40: 8 | C40: Grade 8.8 precision galvanised bolts, nuts and washers | D40: t | E40: =E32*0.045 -> 5.458725 | F40: 75750 | G40: =F40*E40 -> 413498.42
A42: 1200HC | C42: CORROSION PROTECTION OF STRUCTURAL STEELWORK
A44: 8.2.1 | B44: 9 | C44: Corrosion protection for all structural steel members must be Hot-Dipped Galvanising applied according to SANS 121 (ISO 1461) | D44: t | E44: =E20+E22+E24+E28 -> 121.305 | F44: 15100 | G44: =F44*E44 -> 1831705.5
A47: SECTION 2 - CARRIED FORWARD | G47: =SUM(G6:G46) -> 9540785.2
A50: PAYMENT REFERS TO | B50: ITEM NO | C50: DESCRIPTION | D50: UNIT | E50: QUANTITY | F50: RATE | G50: AMOUNT
A51: SECTION 2 - BROUGHT FORWARD | G51: =G47 -> 9540785.2
A53: 1200HB | C53: STRUCTURAL STEELWORK (SUNDRY ITEMS)
A55: 8.3.2 | C55: Handrails (Painted black and yellow)
A57: 8.3.2.1 | C57: Handrails assembly complete, tubular section type (painted black and yellow as per mine norm) mild steel system with side fixed stanchoins to steel complete with bolts, ect.
A59: 8.3.2.1a | B59: 10 | C59: Horizontal | D59: m | E59: 830 | F59: 675 | G59: =E59*F59 -> 560250
B61: 11 | C61: Sloped | D61: m | E61: 225 | F61: 675 | G61: =E61*F61 -> 151875
A63: 8.3.2.1c | B63: 12 | C63: Shaped ends | D63: No. | E63: 24 | F63: 1320 | G63: =E63*F63 -> 31680
A65: 8.3.4 | C65: Flooring, complete and installed with frames (Hot-Dip Galvanised)
C67: Open Grid Floors
A69: 8.3.4.1 | B69: 13 | C69: Vitagrid VFE (VE40) series 5/1 centres with 40x4.5mm bearer bars. All panels to be branded and hot dipped galvanised. | D69: m2 | E69: 490 | F69: 2500 | G69: =F69*E69 -> 1225000
A71: 8.3.4 | C71: Frames and Kerbs for Flooring
A73: 8.3.4.1 | B73: 14 | C73: 150mm High x 6mm thick galvanised kicker plates | D73: m | E73: 1055 | F73: 650 | G73: =E73*F73 -> 685750
B75: 15 | C75: Staircase threads | D75: No | E75: 336 | F75: 1190 | G75: =E75*F75 -> 399840
...

Sheet SUMMARY
A1: ='Section 1 - P&G'!A1 -> NAFASI WATER - ARNOT WASTE TREATMENT PLANT | C1: ='Section 1 - P&G'!G1 -> Revision T1
A2: ='Section 1 - P&G'!A2 -> STRUCTURAL STEELWORK SCHEDULE OF QUANTITIES
A3: SUMMARY | C3: ='Section 1 - P&G'!G3 -> 45183
A5: SECTION | B5: DESCRIPTION | C5: AMOUNT (R)
A7: 1 | B7: ='Section 1 - P&G'!A3 -> SECTION 1 : PRELIMINARY AND GENERAL | C7: ='Section 1 - P&G'!G121 -> 4205401.4
A9: 2 | B9: ='Section 2 - RO Building'!A3 -> SECTION 2: RO BUILDING | C9: ='Section 2 - RO Building'!G85 -> 5845105
A11: 3 | B11: ='Section 3 - Chemical Store'!A3 -> SECTION 3: CHEMICAL STORE | C11: ='Section 3 - Chemical Store'!G85 -> 1146121.8
A13: 4 | B13: ='Section 4 - Workshop'!A3 -> SECTION 4: WORKSHOP | C13: ='Section 4 - Workshop'!G85 -> 1361100.2
A15: 5 | B15: ='Section 5 - Piperacks and Stair'!C7 -> SECTION 5: PIPERACKS AND STAICASES | C15: ='Section 5 - Piperacks and Stair'!G112 -> 12674680
A60: TOTAL AMOUNT CARRIED TO LETTER OF TENDER (VAT EXCLUDED) | C60: =SUM(C7:C59) -> 25232409
